Workbook
Name AirMatresses: 'New Gear Checklist'!$E$50:$E$51
Name Backpacks: 'New Gear Checklist'!$E$4:$E$8
Name Hammocks: 'New Gear Checklist'!$E$16:$E$19
Name PackCover: 'New Gear Checklist'!$E$11:$E$13
Name Print_Titles_0: 'New Gear Checklist'!$2:$2
Name SleepingBagLiners: 'New Gear Checklist'!$E$46:$E$47
Name SleepingBags: 'New Gear Checklist'!$E$42:$E$45
Name Tarps: 'New Gear Checklist'!$E$26:$E$27

Sheet New Gear Checklist
B1: =COUNTIFS(B3:B206,"=x",C3:C206,"=0") -> 1 | C1: =COUNTIF(C3:C206,"=0") -> 17 | D1: Need Weight | F1: Pack Weight
C2: grams | D2: ounces | E2: Items | F2: gm | G2: oz | H2: lb | I2: oz | J2: Notes | K2: New
B3: x | C3: gm | D3: ounces | E3: Pack Group | F3: gm | G3: Tot oz | H3: lb | I3: oz | J3: New Items | N3: dropdown samples
A4: P | B4: x | C4: 1290 | D4: =IF(ISBLANK(C4),"", C4/$D$211) -> 45.503448 | E4: Blue Pack | F4: =IF(B4="x",IF(C4=0,"",C4),"") -> 1290 | G4: =IF(B4="x",D4,"") -> 45.503448 | H4: =IF(C4="","",INT(D4/16)) -> 2 | I4: =IF(D4="","",MOD(D4,16)) -> 13.503448 | J4: {=_xlfn._xlws.FILTER(E4:E206,"x"=K4:K206)} -> New Pack | M4: =VLOOKUP(N4,E4:G8,3,FALSE) -> 45.503448 | N4: Blue Pack
C5: 1175 | D5: =IF(ISBLANK(C5),"", C5/$D$211) -> 41.446939 | E5: Orange Pack #1 | F5: =IF(B5="x",IF(C5=0,"",C5),"") | G5: =IF(B5="x",D5,"") | H5: =IF(C5="","",INT(D5/16)) -> 2 | I5: =IF(D5="","",MOD(D5,16)) -> 9.4469391 | J5: New Pack Cover x | M5: =VLOOKUP(N5,E11:G13,3,FALSE) -> 5.1500026 | N5: Orange Pack Cover
C6: 0 | D6: =IF(ISBLANK(C6),"", C6/$D$211) -> 0 | E6: New Pack | F6: =IF(B6="x",IF(C6=0,"",C6),"") | G6: =IF(B6="x",D6,"") | H6: =IF(C6="","",INT(D6/16)) -> 0 | I6: =IF(D6="","",MOD(D6,16)) -> 0 | J6: Griz Arieal Hammock; 1.6ox Hexon | K6: x | M6: =VLOOKUP(N6,E16:G19,3,FALSE) -> 8.2188398 | N6: Bridge Hammock; 1.2 Hexon Olive
C7: 0 | D7: =IF(ISBLANK(C7),"", C7/$D$211) -> 0 | E7: Red Pack | F7: =IF(B7="x",IF(C7=0,"",C7),"") | G7: =IF(B7="x",D7,"") | H7: =IF(C7="","",INT(D7/16)) -> 0 | I7: =IF(D7="","",MOD(D7,16)) -> 0 | J7: bug net new | M7: =VLOOKUP(N7,E50:G51,3,FALSE) | N7: Air matress blue
C8: 0 | D8: =IF(ISBLANK(C8),"", C8/$D$211) -> 0 | E8: Yellow Pack | F8: =IF(B8="x",IF(C8=0,"",C8),"") | G8: =IF(B8="x",D8,"") | H8: =IF(C8="","",INT(D8/16)) -> 0 | I8: =IF(D8="","",MOD(D8,16)) -> 0 | J8: sleeping bag liner #2 | M8: =VLOOKUP(N8,E42:G45,3,FALSE) -> 44.797968 | N8: 15° sleeping bag - Katahdin
A9: P | B9: x | C9: 27 | D9: =IF(ISBLANK(C9),"", C9/$D$211) -> 0.95239775 | E9: Pack hip pockets | F9: =IF(B9="x",IF(C9=0,"",C9),"") -> 27 | G9: =IF(B9="x",D9,"") -> 0.95239775 | H9: =IF(C9="","",INT(D9/16)) -> 0 | I9: =IF(D9="","",MOD(D9,16)) -> 0.95239775 | J9: Top Quilt | M9: =VLOOKUP(N9,E46:G47,3,FALSE) | N9: sleeping bag liner #2
A10: P | B10: x | C10: 143 | D10: =IF(ISBLANK(C10),"", C10/$D$211) -> 5.0441807 | E10: Pack Liner/Garbage bag | F10: =IF(B10="x",IF(C10=0,"",C10),"") -> 143 | G10: =IF(B10="x",D10,"") -> 5.0441807 | H10: =IF(C10="","",INT(D10/16)) -> 0 | I10: =IF(D10="","",MOD(D10,16)) -> 5.0441807 | J10: New Under Quilt
C11: 200 | D11: =IF(ISBLANK(C11),"", C11/$D$211) -> 7.0547981 | E11: Green/Tan Pack Cover | F11: =IF(B11="x",IF(C11=0,"",C11),"") | G11: =IF(B11="x",D11,"") | H11: =IF(C11="","",INT(D11/16)) -> 0 | I11: =IF(D11="","",MOD(D11,16)) -> 7.0547981 | J11: New Rain Pants Xeon
A12: P | B12: x | C12: 146 | D12: =IF(ISBLANK(C12),"", C12/$D$211) -> 5.1500026 | E12: Orange Pack Cover | F12: =IF(B12="x",IF(C12=0,"",C12),"") -> 146 | G12: =IF(B12="x",D12,"") -> 5.1500026 | H12: =IF(C12="","",INT(D12/16)) -> 0 | I12: =IF(D12="","",MOD(D12,16)) -> 5.1500026 | J12: BRS 3000T Stove
D13: =IF(ISBLANK(C13),"", C13/$D$211) | E13: New Pack Cover x | F13: =IF(B13="x",IF(C13=0,"",C13),"") | G13: =IF(B13="x",D13,"") | H13: =IF(C13="","",INT(D13/16)) | I13: =IF(D13="","",MOD(D13,16)) | J13: Ultralight chair | K13: x
B14: x | C14: =SUMIF(B4:B13,"x",F4:F13) -> 1606 | D14: =IF(ISBLANK(C14),"", C14/$D$211) -> 56.650029 | F14: =IF(B14="x",IF(C14=0,"",C14),"") -> 1606 | G14: =IF(B14="x",D14,"") -> 56.650029 | H14: =IF(C14="","",INT(D14/16)) -> 3 | I14: =IF(D14="","",MOD(D14,16)) -> 8.6500291
B15: x | D15: =IF(ISBLANK(C15),"", C15/$D$211) | E15: Shelter Group | G15: =IF(B15="x",D15,"") | H15: =IF(C15="","",INT(D15/16)) | I15: =IF(D15="","",MOD(D15,16))
C16: 384 | D16: =IF(ISBLANK(C16),"", C16/$D$211) -> 13.545212 | E16: Hammock Olive | F16: =IF(B16="x",IF(C16=0,"",C16),"") | G16: =IF(B16="x",D16,"") | H16: =IF(C16="","",INT(D16/16)) -> 0 | I16: =IF(D16="","",MOD(D16,16)) -> 13.545212
A17: H | B17: x | C17: 233 | D17: =IF(ISBLANK(C17),"", C17/$D$211) -> 8.2188398 | E17: Bridge Hammock; 1.2 Hexon Olive | F17: =IF(B17="x",IF(C17=0,"",C17),"") -> 233 | G17: =IF(B17="x",D17,"") -> 8.2188398 | H17: =IF(C17="","",INT(D17/16)) -> 0 | I17: =IF(D17="","",MOD(D17,16)) -> 8.2188398
D18: =IF(ISBLANK(C18),"", C18/$D$211) | E18: Griz Arieal Hammock; 1.6ox Hexon | F18: =IF(B18="x",IF(C18=0,"",C18),"") | G18: =IF(B18="x",D18,"") | H18: =IF(C18="","",INT(D18/16)) | I18: =IF(D18="","",MOD(D18,16)) | K18: x
D19: =IF(ISBLANK(C19),"", C19/$D$211) | F19: =IF(B19="x",IF(C19=0,"",C19),"") | G19: =IF(B19="x",D19,"") | H19: =IF(C19="","",INT(D19/16)) | I19: =IF(D19="","",MOD(D19,16))
A20: H | B20: x | C20: 207 | D20: =IF(ISBLANK(C20),"", C20/$D$211) -> 7.3017161 | E20: Spreader Bars 28" | F20: =IF(B20="x",IF(C20=0,"",C20),"") -> 207 | G20: =IF(B20="x",D20,"") -> 7.3017161 | H20: =IF(C20="","",INT(D20/16)) -> 0 | I20: =IF(D20="","",MOD(D20,16)) -> 7.3017161
C21: 226 | D21: =IF(ISBLANK(C21),"", C21/$D$211) -> 7.9719219 | E21: Spreader Bars 32" | F21: =IF(B21="x",IF(C21=0,"",C21),"") | G21: =IF(B21="x",D21,"") | H21: =IF(C21="","",INT(D21/16)) -> 0 | I21: =IF(D21="","",MOD(D21,16)) -> 7.9719219
C22: 97 | D22: =IF(ISBLANK(C22),"", C22/$D$211) -> 3.4215771 | E22: Tree straps black | F22: =IF(B22="x",IF(C22=0,"",C22),"") | G22: =IF(B22="x",D22,"") | H22: =IF(C22="","",INT(D22/16)) -> 0 | I22: =IF(D22="","",MOD(D22,16)) -> 3.4215771
A23: H | B23: x | C23: 82 | D23: =IF(ISBLANK(C23),"", C23/$D$211) -> 2.8924672 | E23: Tree straps spider poly | F23: =IF(B23="x",IF(C23=0,"",C23),"") -> 82 | G23: =IF(B23="x",D23,"") -> 2.8924672 | H23: =IF(C23="","",INT(D23/16)) -> 0 | I23: =IF(D23="","",MOD(D23,16)) -> 2.8924672 | J23: RTB or DutchGear
C24: 40 | D24: =IF(ISBLANK(C24),"", C24/$D$211) -> 1.4109596 | E24: Whoopie slings #1 | F24: =IF(B24="x",IF(C24=0,"",C24),"") | G24: =IF(B24="x",D24,"") | H24: =IF(C24="","",INT(D24/16)) -> 0 | I24: =IF(D24="","",MOD(D24,16)) -> 1.4109596
A25: H | B25: x | C25: 40 | D25: =IF(ISBLANK(C25),"", C25/$D$211) -> 1.4109596 | E25: UCR | F25: =IF(B25="x",IF(C25=0,"",C25),"") -> 40 | G25: =IF(B25="x",D25,"") -> 1.4109596 | H25: =IF(C25="","",INT(D25/16)) -> 0 | I25: =IF(D25="","",MOD(D25,16)) -> 1.4109596
C26: 750 | D26: =IF(ISBLANK(C26),"", C26/$D$211) -> 26.455493 | E26: Tarp grey & lines | F26: =IF(B26="x",IF(C26=0,"",C26),"") | G26: =IF(B26="x",D26,"") | H26: =IF(C26="","",INT(D26/16)) -> 1 | I26: =IF(D26="","",MOD(D26,16)) -> 10.455493
A27: C | B27: x | C27: 474 | D27: =IF(ISBLANK(C27),"", C27/$D$211) -> 16.719872 | E27: Tarp Forest green & lines | F27: 300 | G27: =IF(B27="x",D27,"") -> 16.719872 | H27: =IF(C27="","",INT(D27/16)) -> 1 | I27: =IF(D27="","",MOD(D27,16)) -> 0.7198716 | J27: 1.1oz polysil 8yds RBTR; 12.9 sq yds;1.1=14.2; 1.6=20.6
A28: C | B28: x | C28: 80 | D28: =IF(ISBLANK(C28),"", C28/$D$211) -> 2.8219193 | E28: stakes AL red | F28: =IF(B28="x",IF(C28=0,"",C28),"") -> 80 | G28: =IF(B28="x",D28,"") -> 2.8219193 | H28: =IF(C28="","",INT(D28/16)) -> 0 | I28: =IF(D28="","",MOD(D28,16)) -> 2.8219193
C29: 115 | D29: =IF(ISBLANK(C29),"", C29/$D$211) -> 4.0565089 | E29: stakes AL orange | F29: =IF(B29="x",IF(C29=0,"",C29),"") | G29: =IF(B29="x",D29,"") | H29: =IF(C29="","",INT(D29/16)) -> 0 | I29: =IF(D29="","",MOD(D29,16)) -> 4.0565089
A30: T | C30: 126 | D30: =IF(ISBLANK(C30),"", C30/$D$211) -> 4.4445228 | E30: stakes Ti | F30: =IF(B30="x",IF(C30=0,"",C30),"") | G30: =IF(B30="x",D30,"") | H30: =IF(C30="","",INT(D30/16)) -> 0 | I30: =IF(D30="","",MOD(D30,16)) -> 4.4445228
A31: H | C31: 311 | D31: =IF(ISBLANK(C31),"", C31/$D$211) -> 10.970211 | E31: bug net original | F31: =IF(B31="x",IF(C31=0,"",C31),"") | G31: =IF(B31="x",D31,"") | H31: =IF(C31="","",INT(D31/16)) -> 0 | I31: =IF(D31="","",MOD(D31,16)) -> 10.970211
A32: H | C32: 0 | D32: =IF(ISBLANK(C32),"", C32/$D$211) -> 0 | E32: bug net new | F32: =IF(B32="x",IF(C32=0,"",C32),"") | G32: =IF(B32="x",D32,"") | H32: =IF(C32="","",INT(D32/16)) -> 0 | I32: =IF(D32="","",MOD(D32,16)) -> 0 | J32: .67oz noseeum RBT; 4oz | K32: x
A33: T | C33: 545 | D33: =IF(ISBLANK(C33),"", C33/$D$211) -> 19.224325 | E33: tent outside | F33: =IF(B33="x",IF(C33=0,"",C33),"") | G33: =IF(B33="x",D33,"") | H33: =IF(C33="","",INT(D33/16)) -> 1 | I33: =IF(D33="","",MOD(D33,16)) -> 3.2243249
A34: T | C34: 305 | D34: =IF(ISBLANK(C34),"", C34/$D$211) -> 10.758567 | E34: tent inside | F34: =IF(B34="x",IF(C34=0,"",C34),"") | G34: =IF(B34="x",D34,"") | H34: =IF(C34="","",INT(D34/16)) -> 0 | I34: =IF(D34="","",MOD(D34,16)) -> 10.758567
B35: x | C35: 71 | D35: =IF(ISBLANK(C35),"", C35/$D$211) -> 2.5044533 | E35: Tyvek 4x3 | F35: =IF(B35="x",IF(C35=0,"",C35),"") -> 71 | G35: =IF(B35="x",D35,"") -> 2.5044533 | H35: =IF(C35="","",INT(D35/16)) -> 0 | I35: =IF(D35="","",MOD(D35,16)) -> 2.5044533
A36: T | C36: 119 | D36: =IF(ISBLANK(C36),"", C36/$D$211) -> 4.1976049 | E36: Tyvek 8x3 footprint | F36: =IF(B36="x",IF(C36=0,"",C36),"") | G36: =IF(B36="x",D36,"") | H36: =IF(C36="","",INT(D36/16)) -> 0 | I36: =IF(D36="","",MOD(D36,16)) -> 4.1976049
C37: 195 | D37: =IF(ISBLANK(C37),"", C37/$D$211) -> 6.8784282 | E37: Tyvek 7.5' x 5' footprint | F37: =IF(B37="x",IF(C37=0,"",C37),"") | G37: =IF(B37="x",D37,"") | H37: =IF(C37="","",INT(D37/16)) -> 0 | I37: =IF(D37="","",MOD(D37,16)) -> 6.8784282
C38: 0 | D38: =IF(ISBLANK(C38),"", C38/$D$211) -> 0 | E38: plastic footprint | F38: =IF(B38="x",IF(C38=0,"",C38),"") | G38: =IF(B38="x",D38,"") | H38: =IF(C38="","",INT(D38/16)) -> 0 | I38: =IF(D38="","",MOD(D38,16)) -> 0
B39: x | C39: 39 | D39: =IF(ISBLANK(C39),"", C39/$D$211) -> 1.3756856 | E39: Mylar blanket | F39: =IF(B39="x",IF(C39=0,"",C39),"") -> 39 | G39: =IF(B39="x",D39,"") -> 1.3756856 | H39: =IF(C39="","",INT(D39/16)) -> 0 | I39: =IF(D39="","",MOD(D39,16)) -> 1.3756856
B40: x | C40: =SUMIF(B16:B39,"x",F16:F39) -> 1052 | D40: =IF(ISBLANK(C40),"", C40/$D$211) -> 37.108238 | F40: =IF(B40="x",IF(C40=0,"",C40),"") -> 1052 | G40: =IF(B40="x",D40,"") -> 37.108238 | H40: =IF(C40="","",INT(D40/16)) -> 2 | I40: =IF(D40="","",MOD(D40,16)) -> 5.1082382
...

Sheet Single Sheet
B1: {=_xlfn._xlws.FILTER('New Gear Checklist'!E1:E79,"x"='New Gear Checklist'!B1:B79)} -> Pack Group | D1: {=_xlfn._xlws.FILTER('New Gear Checklist'!$E80:$E125,"x"='New Gear Checklist'!$B80:$B125)} -> Kitchen Group | F1: {=_xlfn._xlws.FILTER('New Gear Checklist'!$E126:$E179,"x"='New Gear Checklist'!$B126:$B179)} -> Navigation Group | H1: {=_xlfn._xlws.FILTER('New Gear Checklist'!$E180:$E206,"x"='New Gear Checklist'!$B180:$B206)} -> Consumables Group
A2: ¨ | B2: Blue Pack | C2: ¨ | D2: pot .7 gt cup & windscreen | E2: ¨ | F2: Maps | G2: ¨ | H2: Medication
A3: ¨ | B3: Pack hip pockets | C3: ¨ | D3: IsoPro Stove w/ ignitor | E3: ¨ | F3: Compass | G3: ¨ | H3: 24-32 ounces food per day
A4: ¨ | B4: Pack Liner/Garbage bag | C4: ¨ | D4: IsoPro canister 8oz | E4: ¨ | F4: Trail details | G4: ¨ | H4: 64 ounces water
A5: ¨ | B5: Orange Pack Cover | C5: ¨ | D5: IsoPro canister stand | E5: ¨ | F5: pen / pencil
C6: ¨ | D6: cozy for freezer bag meals | E6: ¨ | F6: notepad / journal | H6: Clothing Worn Group
B7: Shelter Group | C7: ¨ | D7: lighter | G7: ¨ | H7: trekking poles
A8: ¨ | B8: Bridge Hammock; 1.2 Hexon Olive | C8: ¨ | D8: spork short | F8: First Aid Group | G8: ¨ | H8: hiking boots
A9: ¨ | B9: Spreader Bars 28" | C9: ¨ | D9: spoon long | E9: ¨ | F9: First aid kit | G9: ¨ | H9: liner socks
A10: ¨ | B10: Tree straps spider poly | C10: ¨ | D10: 3 liter bladder | G10: ¨ | H10: wool socks
A11: ¨ | B11: UCR | C11: ¨ | D11: water bottles collapsable | F11: Repair Group | G11: ¨ | H11: gators
A12: ¨ | B12: Tarp Forest green & lines | C12: ¨ | D12: smart water bottles | E12: ¨ | F12: Tenacious tape | G12: ¨ | H12: tech shirt
A13: ¨ | B13: stakes AL red | C13: ¨ | D13: Water Filter Kit | E13: ¨ | F13: Duct tape on trekking poles | G13: ¨ | H13: underwear
A14: ¨ | B14: Tyvek 4x3 | C14: ¨ | D14: --Filter (New: Versa Filter) | E14: ¨ | F14: extra buckle | G14: ¨ | H14: Kilt / Zip-offs
A15: ¨ | B15: Mylar blanket | C15: ¨ | D15: --CNOC 3 liter | G15: ¨ | H15: runners cap
B16: 0 | C16: ¨ | D16: --tubing | F16: Misc Group | G16: ¨ | H16: pocket knife
B17: Sleeping Group | C17: ¨ | D17: --sawyer squeze | E17: ¨ | F17: phone battery 4,000mAh | G17: ¨ | H17: lip balm
A18: ¨ | B18: 15° sleeping bag - Katahdin | C18: ¨ | D18: --bleach/polar pure/ tablets | E18: ¨ | F18: Camp chair - heavy | G18: ¨ | H18: phone (in zip-loc)
A19: ¨ | B19: sleeping bag liner blue | C19: ¨ | D19: food bag Blue | E19: ¨ | F19: hammock chair (green) | G19: ¨ | H19: license / money / credit card
A20: ¨ | B20: pillow black (Outdoor Vitals) | C20: ¨ | D20: bear bag and rope | E20: ¨ | F20: head lamp | G20: ¨ | H20: bandana
A21: ¨ | B21: Under Quilt Blue 5.0 Climashield | C21: ¨ | D21: red bandana | E21: ¨ | F21: spare batteries 3 AAA | G21: ¨ | H21: belt
A22: ¨ | E22: ¨ | F22: rope pieces | G22: ¨ | H22: suspenders
B23: Sleeping Clothes Group | D23: Hygiene Group | E23: ¨ | F23: eye glass case - soft
B24: Down booties | C24: ¨ | D24: Bathroom kit | E24: ¨ | F24: foam pad 12 x 18
A25: ¨ | B25: Fleece hat | C25: ¨ | D25: --TP
A26: ¨ | B26: long sleeve shirt | C26: ¨ | D26: --wet wipes | F26: Clothing in Pack Group
A27: ¨ | B27: underwear | C27: ¨ | D27: -- hand sanitizer | E27: ¨ | F27: puffy
A28: ¨ | B28: Wool socks | C28: ¨ | D28: --Gold Bond | E28: ¨ | F28: gloves/mittens
A29: ¨ | B29: Liner socks | C29: ¨ | D29: Shovel plastic | E29: ¨ | F29: Liner socks
A30: ¨ | B30: running tights * | C30: ¨ | D30: water jug botom | E30: ¨ | F30: Wool socks
A31: ¨ | B31: camp shoes | C31: ¨ | D31: tooth brush | E31: ¨ | F31: long sleeve shirt
A32: ¨ | C32: ¨ | D32: tooth dots / paste | E32: ¨ | F32: underwear
B33: Rain Gear Group | C33: ¨ | D33: hand sanitizer on pack | E33: ¨ | F33: shorts
B34: Rain jacket white/green | E34: ¨ | F34: zip-offs
A35: ¨ | B35: Rain pants blue FroggTog
A36: ¨

Sheet Single Column
B1: {=_xlfn._xlws.FILTER(_xlfn.CHOOSECOLS( 'New Gear Checklist'!D1:I207,1,2,5,6),"x"='New Gear Checklist'!B1:B207)} -> ounces | C1: Pack Group | D1: lb | E1: oz
B2: 45.503448 | C2: Blue Pack | D2: 2 | E2: 13.503448
B3: 0.95239775 | C3: Pack hip pockets | D3: 0 | E3: 0.95239775
B4: 5.0441807 | C4: Pack Liner/Garbage bag | D4: 0 | E4: 5.0441807
B5: 5.1500026 | C5: Orange Pack Cover | D5: 0 | E5: 5.1500026
B6: 56.650029 | D6: 3 | E6: 8.6500291
C7: Shelter Group
B8: 8.2188398 | C8: Bridge Hammock; 1.2 Hexon Olive | D8: 0 | E8: 8.2188398
B9: 7.3017161 | C9: Spreader Bars 28" | D9: 0 | E9: 7.3017161
B10: 2.8924672 | C10: Tree straps spider poly | D10: 0 | E10: 2.8924672
B11: 1.4109596 | C11: UCR | D11: 0 | E11: 1.4109596
B12: 16.719872 | C12: Tarp Forest green & lines | D12: 1 | E12: 0.7198716
B13: 2.8219193 | C13: stakes AL red | D13: 0 | E13: 2.8219193
B14: 2.5044533 | C14: Tyvek 4x3 | D14: 0 | E14: 2.5044533
B15: 1.3756856 | C15: Mylar blanket | D15: 0 | E15: 1.3756856
B16: 37.108238 | C16: 0 | D16: 2 | E16: 5.1082382
C17: Sleeping Group
B18: 44.797968 | C18: 15° sleeping bag - Katahdin | D18: 2 | E18: 12.797968
B19: 6.2082224 | C19: sleeping bag liner blue | D19: 0 | E19: 6.2082224
B20: 3.1746592 | C20: pillow black (Outdoor Vitals) | D20: 0 | E20: 3.1746592
B21: 31.676044 | C21: Under Quilt Blue 5.0 Climashield | D21: 1 | E21: 15.676044
B22: 85.856893 | D22: 5 | E22: 5.8568934
C23: Sleeping Clothes Group
B24: 2.9630152 | C24: Down booties | D24: 0 | E24: 2.9630152
B25: 3.2804811 | C25: Fleece hat | D25: 0 | E25: 3.2804811
B26: 5.2205506 | C26: long sleeve shirt | D26: 0 | E26: 5.2205506
B27: 2.6808233 | C27: underwear | D27: 0 | E27: 2.6808233
B28: 5.8554825 | C28: Wool socks | D28: 0 | E28: 5.8554825
B29: 1.6578776 | C29: Liner socks | D29: 0 | E29: 1.6578776
B30: 6.6315103 | C30: running tights * | D30: 0 | E30: 6.6315103
B31: 13.580486 | C31: camp shoes | D31: 0 | E31: 13.580486
B32: 41.870227 | D32: 2 | E32: 9.870227
C33: Rain Gear Group
B34: 8.6068537 | C34: Rain jacket white/green | D34: 0 | E34: 8.6068537
B35: 4.5503448 | C35: Rain pants blue FroggTog | D35: 0 | E35: 4.5503448
B36: 13.157199 | D36: 0 | E36: 13.157199
C37: Kitchen Group
B38: 2.7513713 | C38: pot .7 gt cup & windscreen | D38: 0 | E38: 2.7513713
B39: 3.880139 | C39: IsoPro Stove w/ ignitor | D39: 0 | E39: 3.880139
B40: 8.0071959 | C40: IsoPro canister 8oz | D40: 0 | E40: 8.0071959
...

Sheet Gear combos
B1: Backpack | C1: lb | D1: oz | G1: 28.3495 | H1: gram per oz
A2: {=_xlfn._xlws.FILTER(_xlfn.CHOOSECOLS( 'New Gear Checklist'!D1:I207,1,2,5,6),"P"='New Gear Checklist'!A1:A207)} -> 45.503448 | B2: Blue Pack | C2: 2 | D2: 13.503448 | G2: 0.035274 | H2: oz per gram
A3: 0.95239775 | B3: Pack hip pockets | C3: 0 | D3: 0.95239775 | G3: =36*36 -> 1296 | H3: sq. inches per yard
A4: 5.0441807 | B4: Pack Liner/Garbage bag | C4: 0 | D4: 5.0441807
A5: 5.1500026 | B5: Orange Pack Cover | C5: 0 | D5: 5.1500026
A6: =SUM(A2:A5) -> 56.650029 | C6: =INT(A6/16) -> 3 | D6: =A6-(C6*16) -> 8.6500291
B8: Bridge Hammock | C8: lb | D8: oz | F8: gm | G8: oz | H8: Tent Hammock | I8: lb | J8: oz | L8: Hammock weight
A9: {=_xlfn._xlws.FILTER(_xlfn.CHOOSECOLS( 'New Gear Checklist'!D7:I213,1,2,5,6),"H"='New Gear Checklist'!A7:A213)} -> 8.2188398 | B9: Bridge Hammock; 1.2 Hexon Olive | C9: 0 | D9: 8.2188398 | F9: 724 | G9: =F9/$G$1 -> 25.538369 | H9: Hammock w/ bugnet | I9: =INT(G9/16) -> 1 | J9: =MOD(G9,16) -> 9.5383693 | L9: =((36*4)*60)/(36*36) -> 6.6666667 | M9: =L9*1.6 -> 10.666667 | N9: 1.6 OZ Xeon
A10: 7.3017161 | B10: Spreader Bars 28" | C10: 0 | D10: 7.3017161 | E10: Convert to treking poles | F10: 193 | G10: =F10/$G$1 -> 6.8078802 | H10: Poles | I10: =INT(G10/16) -> 0 | J10: =MOD(G10,16) -> 6.8078802 | L10: 6 | M10: =L10*0.67 -> 4.02 | N10: .67 oz bugnet
A11: 2.8924672 | B11: Tree straps spider poly | C11: 0 | D11: 2.8924672 | F11: 303 | G11: =F11/$G$1 -> 10.688019 | H11: straps, stakes, shock cord, bag | I11: =INT(G11/16) -> 0 | J11: =MOD(G11,16) -> 10.688019 | M11: =M10+M9 -> 14.686667
A12: 1.4109596 | B12: UCR | C12: 0 | D12: 1.4109596 | F12: 10 | G12: =F12/$G$1 -> 0.35273991 | H12: pole bag | I12: =INT(G12/16) -> 0 | J12: =MOD(G12,16) -> 0.35273991
A13: 10.970211 | B13: bug net original | C13: 0 | D13: 10.970211 | E13: Lighten bug net | F13: 37 | G13: =F13/$G$1 -> 1.3051377 | H13: bag | I13: =INT(G13/16) -> 0 | J13: =MOD(G13,16) -> 1.3051377
A14: 0 | B14: bug net new | C14: 0 | D14: 0
A15: =SUM(A9:A14) -> 30.794194 | C15: =INT(A15/16) -> 1 | D15: =A15-(C15*16) -> 14.794194
B17: Tarp | C17: lb | D17: oz
A18: {=_xlfn._xlws.FILTER(_xlfn.CHOOSECOLS( 'New Gear Checklist'!D21:I226,1,2,5,6),"C"='New Gear Checklist'!A21:A226)} -> 16.719872 | B18: Tarp Forest green & lines | C18: 1 | D18: 0.7198716 | F18: 490 | G18: =F18/$G$1 -> 17.284255 | H18: Tarp | I18: =INT(G18/16) -> 1 | J18: =MOD(G18,16) -> 1.2842555
A19: 2.8219193 | B19: stakes AL red | C19: 0 | D19: 2.8219193
A20: =SUM(A18:A19) -> 19.541791 | C20: =INT(A20/16) -> 1 | D20: =A20-(C20*16) -> 3.5417909
F21: =SUM(F9:F18) -> 1757 | G21: =F21/$G$1 -> 61.976402 | H21: Total | I21: =INT(G21/16) -> 3 | J21: =MOD(G21,16) -> 13.976402
B22: Tent | C22: lb | D22: oz
A23: {=_xlfn._xlws.FILTER(_xlfn.CHOOSECOLS( 'New Gear Checklist'!D15:I221,1,2,5,6),"T"='New Gear Checklist'!A15:A221)} -> 4.4445228 | B23: stakes Ti | C23: 0 | D23: 4.4445228
A24: 19.224325 | B24: tent outside | C24: 1 | D24: 3.2243249
A25: 10.758567 | B25: tent inside | C25: 0 | D25: 10.758567
A26: 4.1976049 | B26: Tyvek 8x3 footprint | C26: 0 | D26: 4.1976049
A27: 17.213707 | B27: Air matress blue | C27: 1 | D27: 1.2137075
A28: =SUM(A23:A26) -> 38.62502 | C28: =INT(A28/16) -> 2 | D28: =A28-(C28*16) -> 6.6250198
M29: Material Weight gm
B30: Sleeping Bags | F30: gm | G30: oz | I30: lb | J30: oz | M30: Argon 90 | O30: Climashield
A31: {=_xlfn.CHOOSECOLS( 'New Gear Checklist'!D42:I54,1,2,5,6)} -> 38.378102 | B31: 30° sleeping bag | C31: 2 | D31: 6.3781019 | L31: sq yards | M31: 0.9 | N31: 0.67 | O31: 6 | P31: 3.6
A32: 44.797968 | B32: 15° sleeping bag - Katahdin | C32: 2 | D32: 12.797968 | F32: =(O32+M32)*$G$1 -> 798.51092 | G32: =F32/$G$1 -> 28.166667 | H32: New Under Quilt | I32: =INT(G32/16) -> 1 | J32: =MOD(G32,16) -> 12.166667 | L32: =(78*60)/(36*36) -> 3.6111111 | M32: =L32*2*M31 -> 6.5 | N32: =L32*2*N31 -> 4.8388889 | O32: =L32*O31 -> 21.666667 | P32: =L32*P31 -> 13
A33: 55.203795 | B33: 0° sleeping bag - Antero | C33: 3 | D33: 7.2037955 | F33: =(O33+M33)*$G$1 -> 737.087 | G33: =F33/$G$1 -> 26 | H33: New Top Quilt | I33: =INT(G33/16) -> 1 | J33: =MOD(G33,16) -> 10 | L33: =(72*60)/(36*36) -> 3.3333333 | M33: =L33*2*0.9 -> 6 | N33: =L33*2*N31 -> 4.4666667 | O33: =L33*O31 -> 20 | P33: =L33*P31 -> 12
A34: 38.413376 | B34: Fleece sleeping bag | C34: 2 | D34: 6.4133759 | F34: =SUM(F32:F33) -> 1535.5979 | G34: =F34/$G$1 -> 54.166667 | H34: Copmbined | I34: =SUM(I32:I33) -> 2 | J34: =SUM(J32:J33) -> 22.166667
A35: 6.2082224 | B35: sleeping bag liner blue | C35: 0 | D35: 6.2082224 | F35: 128 | G35: =F35/$G$1 -> 4.5150708 | H35: New liner | I35: =INT(G35/16) -> 0 | J35: =MOD(G35,16) -> 4.5150708 | K35: naturehike 4.5oz 29.99
A36: 0 | B36: sleeping bag liner #2 | C36: 0 | D36: 0 | G36: =A35-G35 -> 1.6931516 | H36: Weight Saved | I36: =INT(G36/16) -> 0 | J36: =MOD(G36,16) -> 1.6931516
A37: 3.0335632 | B37: pillow orange/gray | C37: 0 | D37: 3.0335632
A38: 3.1746592 | B38: pillow black (Outdoor Vitals) | C38: 0 | D38: 3.1746592 | G38: =A45-G34 -> 22.313333 | H38: Weight Saved | I38: =INT(G38/16) -> 1 | J38: =MOD(G38,16) -> 6.3133333 | L38: Climashied
A39: 25.079807 | B39: Air matress Big Birtha | C39: 1 | D39: 9.0798074 | L39: 2 | M39: 50 F
A40: 17.213707 | B40: Air matress blue | C40: 1 | D40: 1.2137075 | L40: 3.6 | M40: 40 F
A41: 0 | B41: Top Quilt | D41: 0 | L41: 5 | M41: 30 F
A42: 31.676044 | B42: Under Quilt Blue 5.0 Climashield | C42: 1 | D42: 15.676044 | L42: 6 | M42: 20 F
...
