Workbook
Name central: Hostels_Drops!#REF!
Name central: 'Post Offices'!$A$39
Name HostelN: Hostels_Drops!$B$38
Name HostelN: 'Post Offices'!#REF!
Name Hostels: Hostels_Drops!$B$1
Name Hostels: 'Post Offices'!#REF!
Name HostelV: Hostels_Drops!$B$25
Name HostelV: 'Post Offices'!#REF!
Name Legend: Hostels_Drops!#REF!
Name Legend: 'Post Offices'!$A$1
Name mid: Hostels_Drops!#REF!
Name mid: 'Post Offices'!$A$59
Name New: Hostels_Drops!#REF!
Name New: 'Post Offices'!$A$78

Sheet Itinerary-OLD
B1: day | C1: Date | D1: DESTINATION | E1: LOCATION | F1: DAY MILAGE | G1: extra miles | H1: Total milage | I1: average | J1: Next resupply | K1: Notes | L1: 2027
B2: 1 | C2: 46467 | D2: Amicolola Falls SP | E2: -8.8 | F2: 0 | G2: 0 | H2: 0 | I2: =H2/B2 -> 0 | J2: 5
B3: =B2+1 -> 2 | C3: =C2+1 -> 46468 | D3: Springer Mtn | E3: 0.2 | F3: =E3-E2 -> 9 | H3: =H2+F3+G3 -> 9 | I3: =H3/B3 -> 4.5
B4: =B3+1 -> 3 | C4: =C3+1 -> 46469 | D4: Sassafras Mt 10.7mi | E4: 10.7 | F4: =E4-E3 -> 10.5 | H4: =H3+F4+G4 -> 19.5 | I4: =H4/B4 -> 6.5 | K4: Hawk Mt Shelter at 7.6mi. Gooch Mt Shelter 14.9
B5: =B4+1 -> 4 | C5: =C4+1 -> 46470 | D5: Woods Hole Shelter | E5: 26.8 | F5: =E5-E4 -> 16.1 | H5: =H4+F5+G5 -> 35.6 | I5: =H5/B5 -> 8.9 | K5: Blood Mt Shelter 28.1mi
B6: =B5+1 -> 5 | C6: =C5+1 -> 46471 | D6: Neels Gap | E6: 30.5 | F6: =E6-E5 -> 3.7 | H6: =H5+F6+G6 -> 39.3 | J6: 3 | K6: Neels Gap (Walasi-Yi) $18 - accepts mail-drop $$ good selection of food | L6: Update: Destination & Location
B7: =B6+0 -> 5 | C7: =C6+0 -> 46471 | D7: Whitley Gap Shelter | E7: 36.7 | F7: =E7-E6 -> 6.2 | H7: =H6+F7+G7 -> 45.5 | I7: =H7/B7 -> 9.1
B8: =B7+1 -> 6 | C8: =C7+1 -> 46472 | D8: Blue Mountain Shelter | E8: 48.3 | F8: =E8-E7 -> 11.6 | H8: =H7+F8+G8 -> 57.1 | I8: =H8/B8 -> 9.5166667
B9: =B8+1 -> 7 | C9: =C8+1 -> 46473 | D9: Deep Gap Shelter | E9: 63.1 | F9: =E9-E8 -> 14.8 | H9: =H8+F9+G9 -> 71.9 | I9: =H9/B9 -> 10.271429
B10: =B9+1 -> 8 | C10: =C9+1 -> 46474 | D10: Hiawassee | E10: 66.6 | F10: =E10-E9 -> 3.5 | G10: 3.5 | H10: =H9+F10+G10 -> 78.9 | I10: =H10/B10 -> 9.8625 | J10: 6 | K10: Hiawassee (Dick's Creek Gap) - hitch to town to get supplies. Poteats hold mail for over night guests ($17pp) aka Blueberry Patch (3.5 mi). | L10: Dick''s Creek Gap
B11: =B10+1 -> 9 | C11: =C10+1 -> 46475 | D11: Muskrat Creek Shelter | E11: 78.2 | F11: =E11-E10 -> 11.6 | H11: =H10+F11+G11 -> 90.5 | I11: =H11/B11 -> 10.055556
B12: =B11+1 -> 10 | C12: =C11+1 -> 46476 | D12: Carter Gap Shelters | E12: 90.7 | F12: =E12-E11 -> 12.5 | H12: =H11+F12+G12 -> 103 | I12: =H12/B12 -> 10.3
B13: =B12+1 -> 11 | C13: =C12+1 -> 46477 | D13: Rock Gap Shelter | E13: 102.8 | F13: =E13-E12 -> 12.1 | H13: =H12+F13+G13 -> 115.1 | I13: =H13/B13 -> 10.463636
B14: =B13+1 -> 12 | C14: =C13+1 -> 46478 | D14: Wine Spring Bald | E14: 114.8 | F14: =E14-E13 -> 12 | H14: =H13+F14+G14 -> 127.1 | I14: =H14/B14 -> 10.591667
B15: =B14+1 -> 13 | C15: =C14+1 -> 46479 | D15: Wesser Blad Shelter | E15: 128.2 | F15: =E15-E14 -> 13.4 | H15: =H14+F15+G15 -> 140.5 | I15: =H15/B15 -> 10.807692
B16: =B15+1 -> 14 | C16: =C15+1 -> 46480 | D16: Wesser | E16: 133.9 | F16: =E16-E15 -> 5.7 | G16: 0 | H16: =H15+F16+G16 -> 146.2 | I16: =H16/B16 -> 10.442857 | J16: 3 | K16: Nantahala Outdoor Center (NOC) Post Office closes at noon on Saturday. Purchase food.$14pp. Maild drop at NOC
B17: =B16+1 -> 15 | C17: =C16+1 -> 46481 | D17: Brown Fork Gap Shelter | E17: 149.9 | F17: =E17-E16 -> 16 | H17: =H16+F17+G17 -> 162.2 | I17: =H17/B17 -> 10.813333
B18: =B17+1 -> 16 | C18: =C17+1 -> 46482 | D18: Fontana Dam | E18: 161.5 | F18: =E18-E17 -> 11.6 | G18: 2 | H18: =H17+F18+G18 -> 175.8 | I18: =H18/B18 -> 10.9875 | K18: Fontana Dam PO 2mi W. Mail drop
B19: =B18+0 -> 16 | C19: =C18+1-1 -> 46482 | D19: Fontana Dam Shelter | E19: 162.6 | F19: =E19-E18 -> 1.1 | H19: =H18+F19+G19 -> 176.9 | I19: =H19/B19 -> 11.05625 | J19: 7 | K19: Sleep at shelter after re-supply | N19: GSMNP shelters
B20: =B19 -> 16 | C20: =C19+1 -> 46483 | E20: 162.9 | F20: =E20-E19 -> 0.3 | H20: =H19+F20+G20 -> 177.2 | K20: obtain permit for Smoky's | M20: 162.9
B21: =B20 -> 16 | C21: =C20 -> 46483 | D21: GSMNP estimates | E21: 179.3 | F21: =E21-E20 -> 16.4 | H21: =H20+F21+G21 -> 193.6 | I21: =H21/B21 -> 12.1 | L21: =M21-M20 -> 11 | M21: 173.9 | N21: Mollies Ridge Shelter
B22: =B19+1 -> 17 | C22: =C21+1 -> 46484 | D22: see GSMNP on right | E22: 195.7 | F22: =E22-E21 -> 16.4 | H22: =H21+F22+G22 -> 210 | I22: =H22/B22 -> 12.352941 | L22: =M22-M21 -> 2.5 | M22: 176.4 | N22: Russel Ridge Shelter
B23: =B22+1 -> 18 | C23: =C22+1 -> 46485 | D23: must stay in shelters | E23: 214 | F23: =E23-E22 -> 18.3 | H23: =H22+F23+G23 -> 228.3 | I23: =H23/B23 -> 12.683333 | L23: =M23-M22 -> 2.9 | M23: 179.3 | N23: Spence Field Shelter
B24: =B23+1 -> 19 | C24: =C23+1 -> 46486 | E24: 226.9 | F24: =E24-E23 -> 12.9 | H24: =H23+F24+G24 -> 241.2 | I24: =H24/B24 -> 12.694737 | K24: Mountain Momma's ( 234.9) | L24: =M24-M23 -> 6.3 | M24: 185.6 | N24: Derrick Knob shelter
B25: =B24+1 -> 20 | C25: =C24+1 -> 46487 | E25: 244.5 | F25: =E25-E24 -> 17.6 | H25: =H24+F25+G25 -> 258.8 | I25: =H25/B25 -> 12.94 | K25: Standing Bear Farm(237.3) $15 - holds mail drops | L25: =M25-M24 -> 5.5 | M25: 191.1 | N25: Siler's Blad Shelter
B26: =B25+1 -> 21 | C26: =C25+1 -> 46488 | E26: 257.6 | F26: =E26-E25 -> 13.1 | H26: =H25+F26+G26 -> 271.9 | I26: =H26/B26 -> 12.947619 | L26: =M26-M25 -> 1.7 | M26: 192.8 | N26: Double Spring Gap Shelter
B27: =B26+1 -> 22 | C27: =C26+1 -> 46489 | D27: Hot Spring | E27: 270.7 | F27: =E27-E26 -> 13.1 | G27: 0 | H27: =H26+F27+G27 -> 285 | I27: =H27/B27 -> 12.954545 | J27: 6 | K27: Hot spring. Mail drop | L27: =M27-M26 -> 2.9 | M27: 195.7 | N27: Clingmans Dome
B28: =B27+1 -> 23 | C28: =C27+1 -> 46490 | D28: Zero Day | E28: 270.7 | F28: =E28-E27 -> 0 | H28: =H27+F28+G28 -> 285 | I28: =H28/B28 -> 12.391304 | K28: Zero Day in Hot Springs | L28: =M28-M27 -> 3.4 | M28: 199.1 | N28: Mt Collins Shelter
B29: =B28+1 -> 24 | C29: =C28+1 -> 46491 | E29: 270.7 | F29: =E29-E28 -> 0 | H29: =H28+F29+G29 -> 285 | I29: =H29/B29 -> 11.875 | K29: ***** START HERE ***** | L29: =M29-M28 -> 7.5 | M29: 206.6 | N29: Icewater Spring Shelter
B30: =B29+1 -> 25 | C30: =C29+1 -> 46492 | E30: 270.7 | F30: =E30-E29 -> 0 | H30: =H29+F30+G30 -> 285 | I30: =H30/B30 -> 11.4 | K30: *** estimate mail drops only *** | L30: =M30-M29 -> 7.4 | M30: 214 | N30: Pecks Corner Shelter
B31: =B30+1 -> 26 | C31: =C30+1 -> 46493 | E31: 270.7 | F31: =E31-E30 -> 0 | H31: =H30+F31+G31 -> 285 | I31: =H31/B31 -> 10.961538 | K31: shelters.html, hostel.html | L31: =M31-M30 -> 5.2 | M31: 219.2 | N31: Tri-Corner Knob Shelter
B32: =B31+1 -> 27 | C32: =C31+1 -> 46494 | E32: 270.7 | F32: =E32-E31 -> 0 | H32: =H31+F32+G32 -> 285 | I32: =H32/B32 -> 10.555556 | L32: =M32-M31 -> 7.7 | M32: 226.9 | N32: Cosby Knob shelter
B33: =B32+1 -> 28 | C33: =C32+1 -> 46495 | D33: Erwin | E33: 338.7 | F33: =E33-E32 -> 68 | G33: 3.8 | H33: =H32+F33+G33 -> 356.8 | I33: =H33/B33 -> 12.742857 | J33: 5 | K33: Mail Drop 3.8 miles to town (Erwin, TN) | L33: =M33-M32 -> 2.8 | M33: 229.7 | N33: Mt Cammerer Side trail (Fire tower)
B34: =B33+1 -> 29 | C34: =C33+1 -> 46496 | E34: 338.7 | F34: =E34-E33 -> 0 | H34: =H33+F34+G34 -> 356.8 | I34: =H34/B34 -> 12.303448 | L34: =M34-M33 -> 4.3 | M34: 234 | N34: Davenport Gap Shelter
B35: =B34+1 -> 30 | C35: =C34+1 -> 46497 | E35: 338.7 | F35: =E35-E34 -> 0 | H35: =H34+F35+G35 -> 356.8 | I35: =H35/B35 -> 11.893333 | L35: =M35-M34 -> 0.9 | M35: 234.9 | N35: Mountain Momma's
B36: =B35+1 -> 31 | C36: =C35+1 -> 46498 | E36: 338.7 | F36: =E36-E35 -> 0 | H36: =H35+F36+G36 -> 356.8 | I36: =H36/B36 -> 11.509677 | K36: Roan Mountain (Elk Park 385.5)) | L36: =M36-M35 -> 9.6 | M36: 244.5 | N36: Groundhog Creek Shelter
B37: =B36+1 -> 32 | C37: =C36+1 -> 46499 | E37: 338.7 | F37: =E37-E36 -> 0 | H37: =H36+F37+G37 -> 356.8 | I37: =H37/B37 -> 11.15 | L37: =M37-M36 -> 8.2 | M37: 252.7 | N37: Roaring Fork Shelter
B38: =B37+1 -> 33 | C38: =C37+1 -> 46500 | D38: Kincora Hostel | E38: 409.3 | F38: =E38-E37 -> 70.6 | H38: =H37+F38+G38 -> 427.4 | I38: =H38/B38 -> 12.951515 | J38: 4 | K38: Kincora Hostel. Mail Drop. Spend the night | L38: =M38-M37 -> 4.9 | M38: 257.6 | N38: Walnut Mountain Shelter
B39: =B38+1 -> 34 | C39: =C38+1 -> 46501 | E39: 409.3 | F39: =E39-E38 -> 0 | H39: =H38+F39+G39 -> 427.4 | I39: =H39/B39 -> 12.570588 | L39: =M39-M38 -> 9.9 | M39: 267.5 | N39: Deer Park Mountain Shelter
B40: =B39+1 -> 35 | C40: =C39+1 -> 46502 | E40: 409.3 | F40: =E40-E39 -> 0 | H40: =H39+F40+G40 -> 427.4 | I40: =H40/B40 -> 12.211429
...

Sheet Itinerary
B1: day | C1: Date | D1: DESTINATION | E1: LOCATION | F1: DAY MILAGE | G1: extra miles | H1: Total milage | I1: average | J1: Next resupply days | K1: Notes | L1: =YEAR(C2) -> 2027 | M1: https://www.postholer.com/databook/Appalachian-Trail/3
B2: 1 | C2: 46460 | D2: Amicolola Falls SP | E2: -8.8 | F2: 0 | G2: 0 | H2: 0 | I2: =H2/B2 -> 0 | J2: 5 | M2: https://www.postholer.com/planner/Appalachian-Trail/3
B3: =B2+1 -> 2 | C3: =C2+1 -> 46461 | D3: Black Gap Shelter | E3: -1.5 | F3: =E3-E2 -> 7.3 | H3: =H2+F3+G3 -> 7.3 | I3: =H3/B3 -> 3.65
B4: =B3+1 -> 3 | C4: =C3 -> 46461 | D4: Springer Mtn | E4: 0.2 | F4: =E4-E3 -> 1.7 | H4: =H3+F4+G4 -> 9 | I4: =H4/B4 -> 3
B5: =B4+1 -> 4 | C5: =C4+1 -> 46462 | D5: Stover Creek Shelter (pic) | E5: 2.8 | F5: =E5-E4 -> 2.6 | H5: =H4+F5+G5 -> 11.6 | I5: =H5/B5 -> 2.9
B6: =B5+1 -> 5 | C6: =C5+1 -> 46463 | D6: Sassafras Mt 10.7mi | E6: 10.7 | F6: =E6-E5 -> 7.9 | H6: =H5+F6+G6 -> 19.5 | I6: =H6/B6 -> 3.9 | K6: Hawk Mt Shelter at 7.8mi. Gooch Mt Shelter 15.1
B7: =B6+1 -> 6 | C7: =C6+1 -> 46464 | D7: Woods Hole Shelter | E7: 26.8 | F7: =E7-E6 -> 16.1 | H7: =H6+F7+G7 -> 35.6 | I7: =H7/B6 -> 7.12 | K7: Blood Mt Shelter 28.3mi
B8: =B7+0 -> 6 | C8: =C7+1 -> 46465 | D8: Neels Gap | E8: 30.5 | F8: =E8-E7 -> 3.7 | H8: =H7+F8+G8 -> 39.3 | J8: 3 | K8: Neels Gap (Walasi-Yi) $18 - accepts mail-drop $$ good selection of food | L8: Update: Destination & Location
B9: =B8+1 -> 7 | C9: =C8+1 -> 46466 | D9: Whitley Gap Shelter | E9: 36.7 | F9: =E9-E8 -> 6.2 | H9: =H8+F9+G9 -> 45.5 | I9: =H9/B8 -> 7.5833333
B10: =B9+1 -> 8 | C10: =C9+1 -> 46467 | D10: Blue Mountain Shelter | E10: 48.3 | F10: =E10-E9 -> 11.6 | H10: =H9+F10+G10 -> 57.1 | I10: =H10/B9 -> 8.1571429
B11: =B10+1 -> 9 | C11: =C10+1 -> 46468 | D11: Deep Gap Shelter | E11: 63.1 | F11: =E11-E10 -> 14.8 | H11: =H10+F11+G11 -> 71.9 | I11: =H11/B10 -> 8.9875
B12: =B11+1 -> 10 | C12: =C11+1 -> 46469 | D12: Hiawassee | E12: 66.6 | F12: =E12-E11 -> 3.5 | G12: 3.5 | H12: =H11+F12+G12 -> 78.9 | I12: =H12/B11 -> 8.7666667 | J12: 6 | K12: Hiawassee (Dick's Creek Gap) - hitch to town to get supplies. Poteats hold mail for over night guests ($17pp) aka Blueberry Patch (3.5 mi). | L12: Dick''s Creek Gap
B13: =B12+1 -> 11 | C13: =C12+1 -> 46470 | D13: Muskrat Creek Shelter | E13: 78.2 | F13: =E13-E12 -> 11.6 | H13: =H12+F13+G13 -> 90.5 | I13: =H13/B12 -> 9.05
B14: =B13+1 -> 12 | C14: =C13+1 -> 46471 | D14: Carter Gap Shelters | E14: 90.7 | F14: =E14-E13 -> 12.5 | H14: =H13+F14+G14 -> 103 | I14: =H14/B13 -> 9.3636364
B15: =B14+1 -> 13 | C15: =C14+1 -> 46472 | D15: Rock Gap Shelter | E15: 102.8 | F15: =E15-E14 -> 12.1 | H15: =H14+F15+G15 -> 115.1 | I15: =H15/B14 -> 9.5916667
B16: =B15+1 -> 14 | C16: =C15+1 -> 46473 | D16: Wine Spring Bald | E16: 114.8 | F16: =E16-E15 -> 12 | H16: =H15+F16+G16 -> 127.1 | I16: =H16/B15 -> 9.7769231
B17: =B16+1 -> 15 | C17: =C16+1 -> 46474 | D17: Wesser Blad Shelter | E17: 128.2 | F17: =E17-E16 -> 13.4 | H17: =H16+F17+G17 -> 140.5 | I17: =H17/B16 -> 10.035714
B18: =B17+1 -> 16 | C18: =C17+1 -> 46475 | D18: Wesser | E18: 133.9 | F18: =E18-E17 -> 5.7 | G18: 0 | H18: =H17+F18+G18 -> 146.2 | I18: =H18/B17 -> 9.7466667 | J18: 3 | K18: Nantahala Outdoor Center (NOC) Post Office closes at noon on Saturday. Purchase food.$14pp. Maild drop at NOC
B19: =B18+1 -> 17 | C19: =C18+1 -> 46476 | D19: Brown Fork Gap Shelter | E19: 149.9 | F19: =E19-E18 -> 16 | H19: =H18+F19+G19 -> 162.2 | I19: =H19/B18 -> 10.1375
B20: =B19+0 -> 17 | C20: =C19+1 -> 46477 | D20: Fontana Dam | E20: 161.5 | F20: =E20-E19 -> 11.6 | G20: 2 | H20: =H19+F20+G20 -> 175.8 | I20: =H20/B19 -> 10.341176 | K20: Fontana Dam PO 2mi W. Mail drop
B21: =B20 -> 17 | C21: =C20+1-1 -> 46477 | D21: Fontana Dam Shelter | E21: 162.6 | F21: =E21-E20 -> 1.1 | H21: =H20+F21+G21 -> 176.9 | I21: =H21/B20 -> 10.405882 | J21: 7 | K21: Sleep at shelter after re-supply | N21: GSMNP shelters
B22: =B21 -> 17 | C22: =C21+1 -> 46478 | E22: 162.9 | F22: =E22-E21 -> 0.3 | H22: =H21+F22+G22 -> 177.2 | K22: obtain permit for Smoky's | M22: 162.9
B23: =B20+1 -> 18 | C23: =C22 -> 46478 | D23: GSMNP estimates | E23: 179.3 | F23: =E23-E22 -> 16.4 | H23: =H22+F23+G23 -> 193.6 | I23: =H23/B22 -> 11.388235 | L23: =M23-M22 -> 11 | M23: 173.9 | N23: Mollies Ridge Shelter
B24: =B23+1 -> 19 | C24: =C23+1 -> 46479 | D24: see GSMNP on right | E24: 195.7 | F24: =E24-E23 -> 16.4 | H24: =H23+F24+G24 -> 210 | I24: =H24/B23 -> 11.666667 | L24: =M24-M23 -> 2.5 | M24: 176.4 | N24: Russel Ridge Shelter
B25: =B24+1 -> 20 | C25: =C24+1 -> 46480 | D25: must stay in shelters | E25: 214 | F25: =E25-E24 -> 18.3 | H25: =H24+F25+G25 -> 228.3 | I25: =H25/B24 -> 12.015789 | L25: =M25-M24 -> 2.9 | M25: 179.3 | N25: Spence Field Shelter
B26: =B25+1 -> 21 | C26: =C25+1 -> 46481 | E26: 226.9 | F26: =E26-E25 -> 12.9 | H26: =H25+F26+G26 -> 241.2 | I26: =H26/B25 -> 12.06 | K26: Mountain Momma's ( 234.9) | L26: =M26-M25 -> 6.3 | M26: 185.6 | N26: Derrick Knob shelter
B27: =B26+1 -> 22 | C27: =C26+1 -> 46482 | E27: 244.5 | F27: =E27-E26 -> 17.6 | H27: =H26+F27+G27 -> 258.8 | I27: =H27/B26 -> 12.32381 | K27: Standing Bear Farm(237.3) $15 - holds mail drops | L27: =M27-M26 -> 5.5 | M27: 191.1 | N27: Siler's Blad Shelter
B28: =B27+1 -> 23 | C28: =C27+1 -> 46483 | E28: 257.6 | F28: =E28-E27 -> 13.1 | H28: =H27+F28+G28 -> 271.9 | I28: =H28/B27 -> 12.359091 | L28: =M28-M27 -> 1.7 | M28: 192.8 | N28: Double Spring Gap Shelter
B29: =B28+1 -> 24 | C29: =C28+1 -> 46484 | D29: Hot Spring | E29: 270.7 | F29: =E29-E28 -> 13.1 | G29: 0 | H29: =H28+F29+G29 -> 285 | I29: =H29/B28 -> 12.391304 | J29: 6 | K29: Hot spring. Mail drop | L29: =M29-M28 -> 2.9 | M29: 195.7 | N29: Clingmans Dome
B30: =B29+1 -> 25 | C30: =C29+1 -> 46485 | D30: Zero Day | E30: 270.7 | F30: =E30-E29 -> 0 | H30: =H29+F30+G30 -> 285 | I30: =H30/B29 -> 11.875 | K30: Zero Day in Hot Springs | L30: =M30-M29 -> 3.4 | M30: 199.1 | N30: Mt Collins Shelter
B31: =B30+1 -> 26 | C31: =C30+1 -> 46486 | E31: 270.7 | F31: =E31-E30 -> 0 | H31: =H30+F31+G31 -> 285 | I31: =H31/B30 -> 11.4 | K31: ***** START HERE ***** | L31: =M31-M30 -> 7.5 | M31: 206.6 | N31: Icewater Spring Shelter
B32: =B31+1 -> 27 | C32: =C31+1 -> 46487 | E32: 270.7 | F32: =E32-E31 -> 0 | H32: =H31+F32+G32 -> 285 | I32: =H32/B31 -> 10.961538 | K32: *** estimate mail drops only *** | L32: =M32-M31 -> 7.4 | M32: 214 | N32: Pecks Corner Shelter
B33: =B32+1 -> 28 | C33: =C32+1 -> 46488 | E33: 270.7 | F33: =E33-E32 -> 0 | H33: =H32+F33+G33 -> 285 | I33: =H33/B32 -> 10.555556 | K33: shelters.html, hostel.html | L33: =M33-M32 -> 5.2 | M33: 219.2 | N33: Tri-Corner Knob Shelter
B34: =B33+1 -> 29 | C34: =C33+1 -> 46489 | E34: 270.7 | F34: =E34-E33 -> 0 | H34: =H33+F34+G34 -> 285 | I34: =H34/B33 -> 10.178571 | L34: =M34-M33 -> 7.7 | M34: 226.9 | N34: Cosby Knob shelter
B35: =B34+1 -> 30 | C35: =C34+1 -> 46490 | D35: Erwin | E35: 338.7 | F35: =E35-E34 -> 68 | G35: 3.8 | H35: =H34+F35+G35 -> 356.8 | I35: =H35/B34 -> 12.303448 | J35: 5 | K35: Mail Drop 3.8 miles to town (Erwin, TN) | L35: =M35-M34 -> 2.8 | M35: 229.7 | N35: Mt Cammerer Side trail (Fire tower)
B36: =B35+1 -> 31 | C36: =C35+1 -> 46491 | E36: 338.7 | F36: =E36-E35 -> 0 | H36: =H35+F36+G36 -> 356.8 | I36: =H36/B35 -> 11.893333 | L36: =M36-M35 -> 4.3 | M36: 234 | N36: Davenport Gap Shelter
B37: =B36+1 -> 32 | C37: =C36+1 -> 46492 | E37: 338.7 | F37: =E37-E36 -> 0 | H37: =H36+F37+G37 -> 356.8 | I37: =H37/B36 -> 11.509677 | L37: =M37-M36 -> 0.9 | M37: 234.9 | N37: Mountain Momma's
B38: =B37+1 -> 33 | C38: =C37+1 -> 46493 | E38: 338.7 | F38: =E38-E37 -> 0 | H38: =H37+F38+G38 -> 356.8 | I38: =H38/B37 -> 11.15 | K38: Roan Mountain (Elk Park 385.5)) | L38: =M38-M37 -> 9.6 | M38: 244.5 | N38: Groundhog Creek Shelter
B39: =B38+1 -> 34 | C39: =C38+1 -> 46494 | E39: 338.7 | F39: =E39-E38 -> 0 | H39: =H38+F39+G39 -> 356.8 | I39: =H39/B38 -> 10.812121 | L39: =M39-M38 -> 8.2 | M39: 252.7 | N39: Roaring Fork Shelter
B40: =B39+1 -> 35 | C40: =C39+1 -> 46495 | D40: Kincora Hostel | E40: 409.3 | F40: =E40-E39 -> 70.6 | H40: =H39+F40+G40 -> 427.4 | I40: =H40/B39 -> 12.570588 | J40: 4 | K40: Kincora Hostel. Mail Drop. Spend the night | L40: =M40-M39 -> 4.9 | M40: 257.6 | N40: Walnut Mountain Shelter
...

Sheet Postholer
B1: PostHoler AT Plan with details
A2: X | B2: Description | C2: Trail | D2: Arrive | E2: Trip | F2: Total | G2: Miles | H2: Section | I2: Section | J2: Section | K2: Section | L2: Zeros/
C3: Mile | D3: (depart) | E3: Mile | F3: Days | G3: From | H3: Miles | I3: Days | J3: MPD | K3: Rating | L3: Neros
G4: Last
B5: 1 - Springer MtnNotes | C5: 0 | D5: Mon, Mar 15 | E5: 0 | F5: 0 | G5: 0 | H5: 0 | I5: 0 | J5: 0 | K5: -
B6: Springer Mountain Shelter | C6: 0.2 | D6: Mon, Mar 15 | E6: 0.2 | F6: 0 | G6: 0.2
B7: USFS 42 TH | C7: 1 | D7: Mon, Mar 15 | E7: 1 | F7: 0.1 | G7: 0.8
B8: Stover Creek Shelter | C8: 2.6 | D8: Mon, Mar 15 | E8: 2.6 | F8: 0.2 | G8: 1.6
B9: Three Forks TH | C9: 4.3 | D9: Mon, Mar 15 | E9: 4.3 | F9: 0.4 | G9: 1.8
B10: Hawk Mountain Shelter | C10: 8.1 | D10: Mon, Mar 15 | E10: 8.1 | F10: 0.7 | G10: 3.8
B11: USFS 42 (Hightower Gap) TH | C11: 8.6 | D11: Mon, Mar 15 | E11: 8.6 | F11: 0.8 | G11: 0.5
B12: Horse Gap TH | C12: 10.5 | D12: Mon, Mar 15 | E12: 10.5 | F12: 0.9 | G12: 1.9
B13: Cooper Gap (pull-off 2) TH | C13: 12.2 | D13: Tue, Mar 16 | E13: 12.2 | F13: 1.1 | G13: 1.7
B14: Cooper Gap (pull-off 1) TH | C14: 12.2 | D14: Tue, Mar 16 | E14: 12.2 | F14: 1.1 | G14: 0
B15: Gooch Mountain Shelter | C15: 15.7 | D15: Tue, Mar 16 | E15: 15.7 | F15: 1.4 | G15: 3.5
B16: Gooch Gap Shelter | C16: 17.1 | D16: Tue, Mar 16 | E16: 17.1 | F16: 1.6 | G16: 1.5
B17: USFS 42 (Gooch Gap) TH | C17: 17.2 | D17: Tue, Mar 16 | E17: 17.2 | F17: 1.6 | G17: 0.1
... B29: Blue Mountain Shelter | C29: 51 | D29: Fri, Mar 19 | E29: 51 | F29: 4.6 | G29: 7.4
B30: 1 - Helen GA 30545/Hiawassee GA 30546/SR 75Notes | C30: 53.3 | D30: Fri, Mar 19 | E30: 53.2 | F30: 4.8 | G30: 2.2 | H30: 53.2 | I30: 4.8 | J30: 11.1 | K30: 5 | L30: 0.5
D31: Sat, Mar 20
B32: USFS 283 (Indian Grave Gap) TH | C32: 55.8 | D32: Sat, Mar 20 | E32: 55.8 | F32: 5.6 | G32: 2.6
B33: USFS 79 (Tray Gap) TH | C33: 57.6 | D33: Sat, Mar 20 | E33: 57.6 | F33: 5.8 | G33: 1.8
B34: Tray Mountain Shelter | C34: 58.9 | D34: Sat, Mar 20 | E34: 58.9 | F34: 5.9 | G34: 1.3
B35: Deep Gap Shelter | C35: 66.2 | D35: Sun, Mar 21 | E35: 66.2 | F35: 6.7 | G35: 7.3
B36: Dicks Creek Gap TH | C36: 69.8 | D36: Mon, Mar 22 | E36: 69.8 | F36: 7 | G36: 3.6
B37: Plumorchard Gap Shelter | C37: 74.5 | D37: Mon, Mar 22 | E37: 74.5 | F37: 7.5 | G37: 4.6
B38: Blue Ridge Gap TH | C38: 75.7 | D38: Mon, Mar 22 | E38: 75.7 | F38: 7.6 | G38: 1.2
B39: Muskrat Creek Shelter | C39: 81.8 | D39: Tue, Mar 23 | E39: 81.7 | F39: 8.3 | G39: 6
B40: Deep Gap TH | C40: 85.7 | D40: Tue, Mar 23 | E40: 85.7 | F40: 8.7 | G40: 4
B41: Standing Indian Shelter | C41: 86.7 | D41: Tue, Mar 23 | E41: 86.7 | F41: 8.8 | G41: 0.9
B42: Carter Gap (old shelter) | C42: 94.4 | D42: Wed, Mar 24 | E42: 94.4 | F42: 9.6 | G42: 7.7
B43: Carter Gap Shelter | C43: 94.4 | D43: Wed, Mar 24 | E43: 94.4 | F43: 9.6 | G43: 0.1
... B50: Winding Stair Gap TH | C50: 110.5 | D50: Fri, Mar 26 | E50: 110.5 | F50: 11.2 | G50: 3.1
B51: 2 - Franklin NC 28734/Winding Stair Gap TH/US Hwy 64Notes | C51: 110.6 | D51: Fri, Mar 26 | E51: 110.6 | F51: 11.2 | G51: 0.1 | H51: 57.3 | I51: 5.9 | J51: 9.7 | K51: 6
D52: Fri, Mar 26
B53: Siler Bald Shelter | C53: 114.6 | D53: Sat, Mar 27 | E53: 114.6 | F53: 12.3 | G53: 4.1
B54: Wayah Crest TH | C54: 116.5 | D54: Sat, Mar 27 | E54: 116.5 | F54: 12.5 | G54: 1.9
B55: SR 1310 | C55: 116.6 | D55: Sat, Mar 27 | E55: 116.6 | F55: 12.5 | G55: 0.1
B56: No Official Name Or Unknown TH | C56: 117.9 | D56: Sat, Mar 27 | E56: 117.9 | F56: 12.6 | G56: 1.3
B57: Wayah Bald parking area TH | C57: 120.6 | D57: Sat, Mar 27 | E57: 120.6 | F57: 12.9 | G57: 2.7
...

Sheet Shelters
A1: Shelter or Town Name | B1: Miles off of AT | C1: Miles Since Last Shelter | D1: State | E1: Water? | F1: Miles from Springer | G1: Miles from Katahdin
A2: Amicalola Falls State Park Shelter | B2: 0 | C2: 0 | D2: GA | E2: Y | F2: -8.8 | G2: 2182.9
A3: Black Gap Shelter | B3: 0 | C3: 7.3 | D3: GA | E3: Y | F3: -1.5 | G3: 2175.6
A4: Springer Mountain Terminus | B4: 0 | C4: 1.5 | D4: GA | E4: N | F4: 0 | G4: 2174.1
A5: Springer Mountain Shelter | B5: 0.2 | C5: 1.7 | D5: GA | E5: Y | F5: 0.2 | G5: 2173.9
A6: Stover Creek Shelter | B6: 0 | C6: 2.5 | D6: GA | E6: Y | F6: 2.5 | G6: 2171.6
A7: Hawk Mountain Shelter | B7: 0.2 | C7: 5.3 | D7: GA | E7: Y | F7: 7.6 | G7: 2166.5
A8: Gooch Mountain Shelter | B8: 0.1 | C8: 7.4 | D8: GA | E8: Y | F8: 14.7 | G8: 2159.4
A9: Suches, Georgia | B9: 2 | C9: 6.1 | D9: GA | E9: Y | F9: 20 | G9: 2154.1
A10: Woods Hole Shelter | B10: 0.4 | C10: 12.4 | D10: GA | E10: Y | F10: 27 | G10: 2147.1
A11: Blood Mountain Shelter | B11: 0 | C11: 2.1 | D11: GA | E11: N | F11: 28.3 | G11: 2145.8
A12: Neels Gap & US 19/129 & Walasi-Yi | B12: 0 | C12: 0 | D12: GA | E12: Y | F12: 30.7 | G12: 2143.4
A13: Whitley Gap Shelter | B13: 1.2 | C13: 9.8 | D13: GA | E13: Y | F13: 38.1 | G13: 2136
... A408: Katahdin Terminus | B408: 0 | C408: 5.2 | D408: ME | E408: N | F408: 2174.1 | G408: 0

Sheet Resupply
A1: NoBo Mile | B1: Dist from Trail | D1: Town or Business | E1: Mail drop or where to buy | F1: Next town days away | G1: Options +1 mile from trail
A2: 0 | D2: Springer Mountain, GA | E2: Buy in Atlanta or before you start | F2: 2
A3: 31.3 | B3: 0 | D3: Neels Gap, GA | E3: Mail to Mountain Crossings | F3: 7
A4: 52.5 | B4: 9 | C4: E | D4: Helen, GA | E4: Mail to Post Office, M–F 9–12:30 & 1:30-4, Sa 9-12 or buy at Betty’s Country Store, Su-Th 7-8, F-Sa 7-9
A5: 52.5 | B5: 12 | C5: E | D5: Hiawassee, GA | E5: Mail to Post Office, M-F 8:30-5, Sa 8:30-12 or buy or shop Ingles
A6: 69.2 | B6: 11 | C6: W | D6: Dicks Creek Gap, GA | E6: Mail to Top of Georgia Hostel
A7: 109.4 | B7: 10 | C7: E | D7: Winding Stair Gap, GA | E7: Mail to to Post Office, M-F 8:30-5, Sa 9-12 or buy at several grocery stores
A8: 136.7 | B8: 0 | D8: Nantahala Outdoor Center, | E8: Mail to NOC Outfitters | F8: 5 | G8: 1-2 to Fantana Village
D9: NC
A10: 164.7 | B10: 2 | C10: W | D10: Fontana Village, NC | E10: Mail to Post Office, M-F: 11:30-3:45 or buy at General Store, Mar 10 thru Thanksgiving | G10: 2-3 Newfound Gap
A11: 207.8 | B11: 15 | C11: W | D11: Newfound Gap. Gatlinburg, TN to the west | E11: Mail to NOC Great Outpost, Open 7 days 10-9, (Jan-May 10-6) or buy at Old Dad’s General Store | G11: 2 to Standing Bear Farm
A12: 241.6 | B12: 0.1 | C12: W | D12: Standing Bear Farm, TN | E12: Mail to Standing Bear Farm or small resupply choices available | F12: 2-3
A13: 275 | B13: 0 | D13: Hot Springs, NC | E13: Mail to Post Office, M-F 9-11:30 & 1-4, Sa 9-10:30 or buy at Hillbilly Market or Bluff Mountain Outfitters, daily 9-5 | F13: 2
A14: 291.3 | B14: 0.7 | C14: W | D14: Hemlock Hallow | E14: Mail to Hemmlock Hollow Under new ownership. | F14: 1-2
E15: There is $5 fee is you don’t spend the night.
A16: 344.4 | B16: 0 | D16: Erwin, TN | E16: Mail to Uncle Johnny’s Nolichucky Hostel | F16: 5
A17: 420 | B17: 0.3 | C17: W | D17: Dennis Cove Rd Black Bear Resort | E17: Mail to Kincora Hiking Hostel Mail to Black Bear Resort | F17: 1
B18: 0.4 | C18: E
A19: 428.6 | B19: 0.1 | C19: W | D19: Boots Off Hostel & Campground | E19: Mail to Boots Off Hostel & Campground | F19: 3
A20: 470.7 | B20: 0 | D20: Damascus, VA | E20: Mail to Post Office, M-F 8:30-1 & 2-4:30, Sa 9-11 or buy at Food City, 7 days | F20: 5
A21: 545.7 | B21: 0 | D21: Atkins, VA | E21: Mail to Relax Inn. There is $5 fee is you don’t spend the night. | F21: 4-5
A22: 591.8 | B22: 4 | C22: E | D22: Bland, VA | E22: Mail to Post Office, M-F 8:30-11:30 & 12-4, Sa 9 -11 or buy at Grants Supermarket, M-Sa 8-8, Su 10-6
A23: 610.2 | B23: 0.5 | C23: W | D23: Trents Grocery | E23: Mail to Trents Grocery | F23: 1
A24: 625.4 | B24: 0.5 | C24: E | D24: Wood Hole Hostel Sugar Run Gap, VA | E24: Mail to Woods Hole Hostel | F24: 5-6
E25: There is $5 fee is you don’t spend the night.
A26: 637.1 | B26: 1.3 | C26: E | D26: Pearisburg, VA | E26: Mail to Post Office, M-F 9-4:30, Sa 10-12 or buy at Food Lion, 7-11
A27: 704.6 | B27: 1 | C27: W | D27: Catawba, VA | E27: Buy at Catawba Grocery | F27: 1-2
A28: 730.3 | B28: 0 | D28: Daleville, VA | E28: Buy at Kroger Grocery, 24 hr | F28: 10-11 | G28: 3-4 to Glasgow
A29: 787.3 | B29: 5.9 | C29: W | D29: Glasgow, VA | E29: Buy at Glasgow Grocery Express, M-Sa 6-11:30pm, Su 8-1130pm | G29: 5 to Waynesboro
A30: 864.3 | B30: 3.7 | C30: W | D30: Waynesboro, VA | E30: Buy at Martin’s, Wal-mat, Target | G30: 1-2 to Loft Mountain
A31: 892.1 | B31: 0 | D31: Loft Mountain Campground, VA | E31: Buy at Campstore, Open May 4-Oct 30 | F31: 2-3
A32: 925.9 | B32: 0 | D32: Big Meadows, VA | E32: Buy small resupplies at Big Meadows Wayside, Open Mar 25 - Nov 13 | F32: 3
A33: 972.1 | B33: 0.3 | C33: E | D33: Front Royal | E33: Mail to Mountain Home or go into Front Royal (3.5W) to Martin’s. | F33: 2
A34: 1005.6 | B34: 0.2 | C34: E | D34: Bears Den | E34: Mail to Bears Den. | F34: 1
E35: Don’t open the store until 5pm so you can’t technically pick them up until 5. A lot of times we are on site all day so if that person let’s us know that they have a drop we will open up and let them get it early.
E36: We stock the basics, tuna, pasta sides, instant potatoes, oatmeal, crackers, snickers, cliff bars etc
A37: 1019.8 | B37: 0.3 | C37: E | D37: Keys Gap | E37: Mail to or buy at Sweet Springs Country Store, M-Sa 4am-11pm, Su 7am-11pm | F37: 6 miles
A38: 1026.4 | B38: 0 | D38: Harpers Ferry, WV | E38: Buy at General Store or The Outfitter | F38: 6
A39: 1057 | B39: 1.5 | C39: W | D39: Smithsburg, MD | E39: Buy at Food Lion, daily 7-11
A40: 1067.1 | B40: 1.2 | C40: E | D40: Waynesboro, PA | E40: Buy at Wal-mart and others
...

Sheet Post Offices
A1: Legend
A2: Services | E2: PO Count by mile range
A3: P = post office | B3: C = camping | E3: =COUNTIF(E24:E95,0) -> 8 | F3: 0 miles from trail
A4: M = meals | B4: O = outfitters | E4: =COUNTIFS(E25:E96,">0",E25:E96,"<=2") -> 22 | F4: <= 2 miles from the trail
A5: G = grocery | B5: H =hostel | E5: =COUNTIFS(E26:E97,">2",E26:E97,"<=5") -> 16 | F5: 2-5 miles
A6: g = small grocery | B6: I = Internet
A7: L = lodging | B7: $ = bank or ATM
A8: cl = laundromat
A9: Sh = shower
A11: Delivery | B11: Type
A12: USPS — United States Post Office | B12: P — Post Office
A13: UPS — United Parcel Service | B13: H — Hostel
A14: FedEx | B14: S — Store
A17: M-O-T — Miles off trail to town.
A18: Miles — Number of trail miles to the next trail town. | F18: 2020 Appalachian Trail Post Offices listing (whiteblaze.net)
A21: Georgia-North Carolina-Tennessee | E21: Appalachian Long Distance Hikers Association - AT Mailing Labels (aldha.org)
A22: Location | B22: Website | C22: Miles | D22: Miles | E22: M-O-T | F22: Services | G22: Delivery | H22: Miles north | I22: Miles south
C23: S-N | D23: N-S
A24: Springer Mountain | B24: www | C24: 20.5 | D24: -- | E24: * | H24: 0 | I24: 2193
A25: Suches, GA | B25: www | C25: 31.8 | D25: 21.1 | E25: 2 | F25: P, g, C, cl, S, I, | G25: USPS | H25: 20.5 | I25: 2172.5
A26: Helen, GA | B26: www | C26: 16.9 | D26: 31.8 | E26: 9 | F26: P, G, M, L, I, | G26: USPS | H26: 52.5 | I26: 2140.5
A27: Hiawassee, GA | B27: www | C27: 40.2 | D27: 16.9 | E27: 11 | F27: All, drop | G27: USPS | H27: 69.2 | I27: 2123.8
A28: Franklin, NC | B28: www | C28: 27.3 | D28: 40.2 | E28: 10 | F28: All, Hostels | G28: USPS | H28: 109.4 | I28: 2083.6
A29: Bryson City, NC | B29: www | C29: 27.6 | D29: 27.3 | E29: 13 | F29: P, G, M, L, I, $, drop | G29: USPS | H29: 136.7 | I29: 2056.3
A30: Fontana Village, NC | B30: www | C30: 42.6 | D30: 27.6 | E30: 1.8 | F30: P, g, M, L, hostel | G30: USPS | H30: 164.7 | I30: 2028.3
A31: Gatlinburg, TN | B31: www | C31: 67.1 | D31: 42.6 | E31: 15 | F31: All, drop | G31: USPS | H31: 207.7 | I31: 1985.3
A32: Hot Springs, NC | B32: www | C32: 68.6 | D32: 67.1 | E32: 0 | F32: All, hostels, drop | G32: USPS | H32: 274.9 | I32: 1918.1
A33: Erwin, TN | B33: www | C33: 50.8 | D33: 68.6 | E33: 3.8 | F33: P, G, L, cl, C, I, $, hostel | G33: USPS | H33: 344.3 | I33: 1848.7
A34: Roan Mountain, TN | B34: www | C34: 33.3 | D34: 50.8 | E34: 3.4 | F34: P, M, g, $, hostel | G34: USPS | H34: 395.3 | I34: 1797.7
A35: Elk Park, NC | B35: www | C35: '' | D35: '' | E35: 2.5 | F35: P, M, g | G35: USPS | H35: " | I35: "
A36: Hampton, TN | B36: www | C36: 27 | D36: 33.3 | E36: 2 | F36: P, M, G, L, $, hostel, drop | G36: USPS | H36: 428.6 | I36: 1764.4
A37: Shady Valley, TN | B37: www | C37: 15 | D37: 27 | E37: 2.7 | F37: P, M, g | G37: USPS | H37: 455.7 | I37: 1737.3
A39: Virginia-West Virginia
A40: Location | B40: Website | C40: Miles | D40: Miles | E40: M-O-T | F40: Services | G40: Delivery | H40: Miles north | I40: Miles south
C41: S-N | D41: N-S
A42: Damascus, VA | B42: www | C42: 47.7 | D42: 15 | E42: 0 | F42: All, hostels, drop | G42: USPS | H42: 471.5 | I42: 1720.5
A43: Troutdale, VA | B43: www | C43: 24.8 | D43: 47.7 | E43: 2.6 | F43: P, hostel | G43: USPS | H43: 520 | I43: 1672
A44: Atkins, VA | B44: www | C44: 46.5 | D44: 24.8 | E44: 3.2 | F44: P, M, G, L | G44: USPS | H44: 545.5 | I44: 1646.5
A45: Bland, VA | B45: www | C45: 45.7 | D45: 46.5 | E45: 2.7 | F45: P, M, G, L, cl, I, $ | G45: USPS | H45: 591.6 | I45: 1600.4
A46: Pearisburg, VA | B46: www | C46: 73.1 | D46: 45.7 | E46: 1 | F46: P, M, G, L, cl, I, $, hostel, drops | G46: USPS | H46: 636.9 | I46: 1555.1
...

Sheet Hostels_Drops
B1: Hostels, Lodging & Drops
B2: Trail Crossing | C2: Location | D2: Mileage | E2: M-O-T | F2: Website | G2: Phone | H2: Delivery
A3: =E3 -> -- | B3: Approach Trail | C3: Amicalola Falls State Park | D3: -- | E3: -- | F3: www | G3: 706.344.1500 | H3: USPS or UPS
A4: =IF(E4="""",E3,E4) -> 0 | B4: Neel Gap | C4: Mountain Crossings (g) | D4: 31.3 | E4: 0 | F4: www | G4: 706.745.6095 | H4: USPS or UPS
A5: =IF(E5="""",E4,E5) -> 11 | B5: Dick's Creek Gap | C5: Hiawassee Budget Inn | D5: " | E5: 11 | F5: www | G5: 706.896.4121 | H5: UPS
A6: =IF(E6="""",E5,E6) -> 10 | B6: Winding Stair Gap | C6: Budget Inn | D6: 109.4 | E6: 10 | G6: 828.524.4403 | H6: USPS
A7: =IF(E7="""",E6,E7) -> 10 | B7: Winding Stair Gap | C7: "Baltimore Jack" Tarlin Hostel | D7: " | E7: " | F7: www | G7: 828.524.2604 | H7: USPS
A8: =IF(E8="""",E7,E8) -> 2 | B8: Burningtown Gap | C8: Aquone Hostel | D8: 125 | E8: 2 | F8: www | G8: 828.321.2340 | H8: USPS
A9: =IF(E9="""",E8,E9) -> 0 | B9: Wesser, NC | C9: Nantahala Outdoor Center | D9: 137.7 | E9: 0 | F9: www | G9: 888.905.7238 | H9: All
A10: =IF(E10="""",E9,E10) -> 2 | B10: Fontana Dam | C10: Fontana Lodge | D10: 164.5 | E10: 2 | F10: www | G10: 800.849.2258 | H10: USPS
A11: =IF(E11="""",E10,E11) -> 6 | B11: Fontana Dam | C11: The Hike Inn | D11: " | E11: 6 | F11: www | G11: 828.479.3677 | H11: USPS
A12: =IF(E12="""",E11,E12) -> 15 | B12: Newfound Gap | C12: The Appy Lodge | D12: 207.7 | E12: 15 | F12: www | G12: 800.732.2802 | H12: All
A13: =IF(E13="""",E12,E13) -> 15 | B13: Newfound Gap | C13: Motel 6 | D13: 207.7 | E13: 15 | F13: www | G13: 800.732.2802 | H13: All
A14: =IF(E14="""",E13,E14) -> 0.1 | B14: Green Corner Rd. | C14: Standing Bear Farm (g) | D14: 241.5 | E14: 0.1 | G14: 423.487.0014 | H14: USPS
A15: =IF(E15="""",E14,E15) -> 0 | B15: Hot Springs, NC | C15: The Hostel @ The Laughing Heart Lodge | D15: 274.9 | E15: 0 | F15: www | G15: 828.206.8487 | H15: USPS
A16: =IF(E16="""",E15,E16) -> 0 | B16: Hot Springs, NC | C16: The Sunnybank Inn | D16: " | E16: " | F16: www | G16: 828.622.3231 | H16: USPS
A17: =IF(E17="""",E16,E17) -> " | B17: Hot Springs, NC | C17: Bluff Mountain Outfitters (g) | D17: " | E17: " | F17: www | G17: 828.622.7162 | H17: USPS
A18: =IF(E18="""",E17,E18) -> 0 | B18: Erwin, TN | C18: Nolichucky Hostel | D18: 344.3 | E18: 0 | F18: www | G18: 423.735.0548 | H18: USPS or UPS
A19: =IF(E19="""",E18,E19) -> 0.6 | B19: Greasy Creek Gap | C19: Greasy Creek Friendly | D19: 368.5 | E19: 0.6 | G19: 828.688.9948 | H19: USPS
A20: =IF(E20="""",E19,E20) -> 0.3 | B20: 19E | C20: Mountain Harbour Hostel | D20: 395.2 | E20: 0.3 | F20: www | G20: 866.772.9494 | H20: USPS
A21: =IF(E21="""",E20,E21) -> 0.7 | B21: 19E | C21: The Station @ 19E | D21: 395.2 | E21: 0.7 | F21: www | G21: 423.250.3700 | H21: USPS
A22: =IF(E22="""",E21,E22) -> 0.4 | B22: Upper Laurel Fork | C22: Vango Solar Hostel | D22: 407.6 | E22: 0.4 | G22: 423.772.3450 | H22: USPS
A23: =IF(E23="""",E22,E23) -> 0.2 | B23: Dennis Cove Rd. | C23: Kincora Hostel | D23: 419.9 | E23: 0.2 | G23: 423.725.4409 | H23: USPS
A24: =IF(E24="""",E23,E24) -> 0.4 | B24: Dennis Cove Rd. | C24: Black Bear Resort | D24: " | E24: 0.4 | F24: www | G24: 423.725.5988 | H24: USPS
A25: =IF(E25="""",E24,E25) -> 0 | B25: Damascus, VA | C25: Mount Rogers Outfitters | D25: 470.5 | E25: 0 | F25: www | G25: 276.475.5416 | H25: USPS
A26: =IF(E26="""",E25,E26) -> 0 | B26: Atkins, VA | C26: The Relax Inn | D26: 545.5 | E26: 0 | G26: 276.783.5811 | H26: USPS
A27: =IF(E27="""",E26,E27) -> 0.5 | B27: VA 606 | C27: Trent Grocery | D27: 607 | E27: 0.5 | G27: 276.928.1349 | H27: USPS
A28: =IF(E28="""",E27,E28) -> 0.5 | B28: Sugar Run Gap | C28: Woodshole Hostel | D28: 625.2 | E28: 0.5 | F28: www | G28: 540.921.3444 | H28: USPS
A29: =IF(E29="""",E28,E29) -> 1 | B29: Pearisburg, VA | C29: Holiday Motor Lodge | D29: 635.6 | E29: 1 | G29: 540.921.1551 | H29: USPS
A30: =IF(E30="""",E29,E30) -> 1 | B30: Pearisburg, VA | C30: Plaza Motel | D30: " | E30: " | G30: 540.921.2591 | H30: USPS
A31: =IF(E31="""",E30,E31) -> 0.4 | B31: VA 624 | C31: 4 Pines Hostel | D31: 703.9 | E31: 0.4 | F31: www | G31: 540.309.8615 | H31: USPS or UPS
A32: =IF(E32="""",E31,E32) -> 0 | B32: US 220 | C32: Howard Johnsons Express Inn | D32: 729.6 | E32: 0 | F32: www | G32: 540.992.1234 | H32: USPS or UPS
A33: =IF(E33="""",E32,E33) -> 0.5 | B33: US 11 | C33: The Comfort Inn | D33: 731.3 | E33: 0.5 | F33: www | G33: 540.992.5600 | H33: USPS or UPS
A34: =IF(E34="""",E33,E34) -> 0.1 | B34: Snickers Gap | C34: Bears Den Trail Center | D34: 1005.5 | E34: 0.1 | F34: www | G34: 540.554.8708 | H34: USPS
A35: =IF(E35="""",E34,E35) -> 0.2 | B35: Harpers Ferry | C35: ATC Headquarters | D35: 1024.7 | E35: 0.2 | F35: www | G35: 304.535.6848 | H35: USPS, UPS or FedEx
A36: =IF(E36="""",E35,E36) -> 0 | B36: Duncannon, PA | C36: Kind Of Outdoorsy | D36: 1149 | E36: 0 | F36: www | H36: USPS
A37: =IF(E37="""",E36,E37) -> 1 | B37: Port Clinton, PA | C37: Microtel Inn | D37: 1219.1 | E37: 1 | F37: www | G37: 610.562.4234 | H37: USPS
A38: =IF(E38="""",E37,E38) -> 0 | B38: Salisbury, CT | C38: Maria McCabe | D38: 1501.1 | E38: 0 | G38: 860.435.0593 | H38: USPS
A39: =IF(E39="""",E38,E39) -> 1.6 | B39: MA 23 | C39: East Mountain Retreat | D39: 1531.2 | E39: 1.6 | F39: www | G39: 413.528.6617 | H39: UPS or FedEx
A40: =IF(E40="""",E39,E40) -> 2 | B40: Williamstown, MA | C40: The Willow Motel | D40: 1.594.4 | E40: 2 | F40: www | G40: 413.458.5768 | H40: USPS
...

Sheet MailDrops
E1: Update Mail Drop locations and address
A2: Drop Number: | B2: Date to ship: | C2: Date to arrive: | D2: Postage: | E2: Mail to: | F2: Contents: | G2: Added stuff requested: | H2: notes
A3: 1 | B3: =SUM(C3,-9) -> 46462 | C3: ='Itinerary-OLD'!C6 -> 46471 | E3: =("David Smith c/o General Dilevery Neels Gap Hold for A.T. Hiker, expected " &TEXT($C3,"d mmmm")) -> David Smith c/o General Dilevery Neels Gap Hold for A.T. Hiker, expected 25 March | F3: Food, maps (1, 2, 3) | H3: Neel's Gap, GA - 30.5 (Walasi-Yi accepts mail drops)
A4: =A3+1 -> 2 | B4: =SUM(C4,-9) -> 46465 | C4: ='Itinerary-OLD'!C10 -> 46474 | E4: =("Hiawassee, Ga (Poteats 3.5m) Hold for A.T. hiker, expected " &TEXT(C4,"d mmmm") ) -> Hiawassee, Ga (Poteats 3.5m) Hold for A.T. hiker, expected 28 March | H4: -Hiawassee, GA (D) - 66.6 (Hitch to town 3.5m)
A5: =A4+1 -> 3 | B5: =SUM(C5,-9) -> 46462 | C5: ='Itinerary-OLD'!C6 -> 46471 | E5: =("NOC, NC Hold for A.T. hiker, expected " &TEXT(C5,"d mmmm") ) -> NOC, NC Hold for A.T. hiker, expected 25 March | H5: accepts mail drops
A6: =A5+1 -> 4 | B6: =SUM(C6,-9) -> 46473 | C6: ='Itinerary-OLD'!C18 -> 46482 | E6: =("David Smith c/o General Dilevery Fontanna Dam, NC 28733 Hold for A.T. Hiker, expected "&TEXT(C6,"d mmmm")) -> David Smith c/o General Dilevery Fontanna Dam, NC 28733 Hold for A.T. Hiker, expected 5 April | H6: Fontanna Dam Shelter PO 2 mi
A7: =A6+1 -> 5 | B7: =SUM(C7,-9) -> 46480 | C7: ='Itinerary-OLD'!C27 -> 46489 | E7: =("Hot Spring, NC Hold for A.T. hiker, expected " &TEXT(C7,"d mmmm") ) -> Hot Spring, NC Hold for A.T. hiker, expected 12 April
A8: =A7+1 -> 6 | B8: =SUM(C8,-9) -> 46486 | C8: ='Itinerary-OLD'!C33 -> 46495 | E8: =("Erwin, TN Hold for A.T. hiker, expected " &TEXT(C8,"d mmmm") ) -> Erwin, TN Hold for A.T. hiker, expected 18 April | H8: PO 3.8 mi
A9: =A8+1 -> 7 | B9: =SUM(C9,-9) -> 46491 | C9: ='Itinerary-OLD'!C38 -> 46500 | E9: =("Kincora, TN Hold for A.T. hiker, expected " &TEXT(C9,"d mmmm") ) -> Kincora, TN Hold for A.T. hiker, expected 23 April | H9: Hostel Spend night, Mail Drop
A10: =A9+1 -> 8 | B10: =SUM(C10,-9) -> 46495 | C10: ='Itinerary-OLD'!C42 -> 46504 | E10: =("Damascus, VA Hold for A.T. hiker, expected " &TEXT(C9,"d mmmm") ) -> Damascus, VA Hold for A.T. hiker, expected 23 April
A11: =A10+1 -> 9 | B11: =SUM(C11,-9) -> 46501 | C11: ='Itinerary-OLD'!C48 -> 46510 | E11: =("Atkins, VA Hold for A.T. hiker, expected " &TEXT(C11,"d mmmm") ) -> Atkins, VA Hold for A.T. hiker, expected 3 May | H11: PO 3.2 mi
A12: =A11+1 -> 10 | B12: =SUM(C12,-9) -> 46507 | C12: ='Itinerary-OLD'!C54 -> 46516 | E12: =("Pearisburg, VA Hold for A.T. hiker, expected " &TEXT(C12,"d mmm") ) -> Pearisburg, VA Hold for A.T. hiker, expected 9 May
A13: =A12+1 -> 11 | B13: =SUM(C13,-9) -> 46513 | C13: ='Itinerary-OLD'!C60 -> 46522 | E13: =("Daleville, VA Hold for A.T. hiker, expected " &TEXT(C13,"d mmmm") ) -> Daleville, VA Hold for A.T. hiker, expected 15 May
A14: =A13+1 -> 12 | B14: =SUM(C14,-9) -> 46521 | C14: ='Itinerary-OLD'!C68 -> 46530 | E14: =("Waynesboro, VA Hold for A.T. hiker, expected " &TEXT(C14,"d mmmm") ) -> Waynesboro, VA Hold for A.T. hiker, expected 23 May | H14: PO 4.5 mi
A15: =A14+1 -> 13 | B15: =SUM(C15,-9) -> 46526 | C15: ='Itinerary-OLD'!C73 -> 46535 | E15: =("Linden, VA Hold for A.T. hiker, expected " &TEXT(C15,"d mmmm") ) -> Linden, VA Hold for A.T. hiker, expected 28 May
A16: =A15+1 -> 14 | B16: =SUM(C16,-9) -> 46530 | C16: ='Itinerary-OLD'!C77 -> 46539 | E16: =("Harpers Ferry, WV Hold for A.T. hiker, expected " &TEXT(C16,"d mmmm") ) -> Harpers Ferry, WV Hold for A.T. hiker, expected 1 June
C17: ='Itinerary-OLD'!C81 -> 46543 | E17: Pine Grove Furnace, Meet with family and friends | H17: Personal delivery
A18: =A16+1 -> 15 | B18: =SUM(C18,-9) -> 46538 | C18: ='Itinerary-OLD'!C85 -> 46547 | E18: =("Duncannon, PA Hold for A.T. hiker, expected " &TEXT(C18,"d mmmm") ) -> Duncannon, PA Hold for A.T. hiker, expected 9 June
A19: =A18+1 -> 16 | B19: =SUM(C19,-9) -> 46543 | C19: ='Itinerary-OLD'!C90 -> 46552 | E19: =("Port Clinton, PA Hold for A.T. hiker, expected " &TEXT(C19,"d mmmm") ) -> Port Clinton, PA Hold for A.T. hiker, expected 14 June
A20: =A19+1 -> 17 | B20: =SUM(C20,-9) -> 46548 | C20: ='Itinerary-OLD'!C95 -> 46557 | E20: =("DWG, PA Hold for A.T. hiker, expected " &TEXT(C20,"d mmmm") ) -> DWG, PA Hold for A.T. hiker, expected 19 June
A21: =A20+1 -> 18 | B21: =SUM(C21,-9) -> 46552 | C21: ='Itinerary-OLD'!C99 -> 46561 | E21: =("Vernon, NJ Hold for A.T. hiker, expected " &TEXT(C21,"d mmmm") ) -> Vernon, NJ Hold for A.T. hiker, expected 23 June | H21: (PO 2.4 mi) Church Hostel, supermarket
A22: =A21+1 -> 19 | B22: =SUM(C22,-9) -> 46556 | C22: ='Itinerary-OLD'!C103 -> 46565 | E22: =("Bear Mountain, NY Hold for A.T. hiker, expected " &TEXT(C22,"d mmmm") ) -> Bear Mountain, NY Hold for A.T. hiker, expected 27 June
A23: =A22+1 -> 20 | B23: =SUM(C23,-9) -> 46561 | C23: ='Itinerary-OLD'!C108 -> 46570 | E23: =("Falls Village, CT Hold for A.T. hiker, expected " &TEXT(C23,"d mmmm") ) -> Falls Village, CT Hold for A.T. hiker, expected 2 July
A24: =A23+1 -> 21 | B24: =SUM(C24,-9) -> 46568 | C24: ='Itinerary-OLD'!C115 -> 46577 | E24: =("Cheshire, MA Hold for A.T. hiker, expected " &TEXT(C24,"d mmmm") ) -> Cheshire, MA Hold for A.T. hiker, expected 9 July
A25: =A24+1 -> 22 | B25: =SUM(C25,-9) -> 46574 | C25: ='Itinerary-OLD'!C121 -> 46583 | E25: =("Manchester Center, VT Hold for A.T. hiker, expected " &TEXT(C25,"d mmmm") ) -> Manchester Center, VT Hold for A.T. hiker, expected 15 July | F25: Food, maps (1, 2, 3), Winter gear | G25: *** Ship winter Gear for Whites *** | H25: PO 5.5 mi
A26: =A25+1 -> 23 | B26: =SUM(C26,-9) -> 46580 | C26: ='Itinerary-OLD'!C127 -> 46589 | E26: =("Hanover, NH Hold for A.T. hiker, expected " &TEXT(C26,"d mmmm") ) -> Hanover, NH Hold for A.T. hiker, expected 21 July
A27: =A26+1 -> 24 | B27: =SUM(C27,-9) -> 46585 | C27: ='Itinerary-OLD'!C132 -> 46594 | E27: =("David Smith c/o General Delivery Glencliff, NH 03238 Hold for A.T. hiker, expected " &TEXT(C27,"d mmmm") ) -> David Smith c/o General Delivery Glencliff, NH 03238 Hold for A.T. hiker, expected 26 July
A28: =A27+1 -> 25 | B28: =SUM(C28,-9) -> 46588 | C28: ='Itinerary-OLD'!C135 -> 46597 | E28: =("North Woodstock, NH Hold for A.T. hiker, expected " &TEXT(C28,"d mmmm") ) -> North Woodstock, NH Hold for A.T. hiker, expected 29 July | H28: PO 5.8 mi
A29: =A28+1 -> 26 | B29: =SUM(C29,-9) -> 46593 | C29: ='Itinerary-OLD'!C140 -> 46602 | E29: =("Gorham, NH Hold for A.T. hiker, expected " &TEXT(C29,"d mmmm") ) -> Gorham, NH Hold for A.T. hiker, expected 3 August | H29: PO 3.6 mi
A30: =A29+1 -> 27 | B30: =SUM(C30,-9) -> 46598 | C30: ='Itinerary-OLD'!C145 -> 46607 | E30: =("Andover, ME Hold for A.T. hiker, expected " &TEXT(C30,"d mmmm") ) -> Andover, ME Hold for A.T. hiker, expected 8 August
A31: =A30+1 -> 28 | B31: =SUM(C31,-9) -> 46604 | C31: ='Itinerary-OLD'!C151 -> 46613 | E31: =("Strantton, ME Hold for A.T. hiker, expected " &TEXT(C31,"d mmmm") ) -> Strantton, ME Hold for A.T. hiker, expected 14 August
A32: =A31+1 -> 29 | B32: =SUM(C32,-9) -> 46609 | C32: ='Itinerary-OLD'!C156 -> 46618 | E32: =("Monson, ME Hold for A.T. hiker, expected " &TEXT(C32,"d mmmm") ) -> Monson, ME Hold for A.T. hiker, expected 19 August
A33: =A32+1 -> 30 | B33: =SUM(C33,-9) -> 46615 | C33: ='Itinerary-OLD'!C162 -> 46624 | E33: =("Abol Bridge, ME Hold for A.T. hiker, expected " &TEXT(C33,"d mmmm") ) -> Abol Bridge, ME Hold for A.T. hiker, expected 25 August
E36: http://www.whiteblaze.net/index.php?page=postoffices
E37: http://www.whiteblaze.net/forum/showthread.php?p=95199&postcount=1
E40: (D) Warren Doyle recommended
E41: (PO #miles) PO followed by number of miles off trail
E42: (PO) PO on trail
E43: - off trail
E46: Neel's Gap, GA - 30.5 (Walasi-Yi accepts mail drops)
...

Sheet Info
A1: ALDHA - Companion | B1: ALDHA - Thru-Hikers' Companion | E1: TABLE 1 -- Days to Complete Various Sections
A2: ALDHA - Planning | B2: Appalachian Long Distance Hikers Association - Planning (aldha.org)
A3: ALDHA - Post Offices / Hostels | B3: Appalachian Long Distance Hikers Association - AT Mailing Labels (aldha.org) | E3: DAYS ~~~ TOTAL DAYS ~~ SECTION
E4: 8.0 days..........(8.0)............Springer to Georgia Border (7.7 days)
A5: WhiteBlaze trail guide | B5: WhiteBlaze Pages guidebooks | E5: 7.9 days.........(15.9)...........Georgia Border to Fontana (7.7 days)
A6: WhiteBlaze Hostels | B6: 2020 Appalachian Trail Hostel listing (whiteblaze.net) | E6: 24.4 days.......(40.3)...........Fontana to Damascus (24 days)
A7: WhiteBlaze Post Offices | B7: 2020 Appalachian Trail Post Offices listing (whiteblaze.net) | E7: 28.7 days.......(69.0)...........Damascus to Waynesboro (28 days)
A8: WhiteBlaze Resupply | B8: Appalachian Trail Resupply listing (whiteblaze.net) | E8: 11.2 days.......(80.2)...........Waynesboro to Harpers Ferry (11 days)
A9: WhiteBlaze Shelters | B9: Appalachian Trail Shelter listing 2020 (whiteblaze.net) | E9: 19.2 days.......(99.3)...........Harpers Ferry to DWG (19 days)
A10: WhiteBlaze Hiking Rates | B10: WhiteBlaze - AT Hiking Rates, Section by Section | C10: -----------------------------> | E10: 12.6 days......(111.9)...........DWG to Kent (12 days)
E11: 23.5 days......(135.4)...........Kent to Glencliff (23.2 days)
A12: Shelters by Mileage | B12: Appalachian Trail Shelters by Mileage | AppalachianTrailTravelGuide.com | E12: 9.7 days........(145.1)..........Glencliff to Gorham (10 days)
E13: 9.9 days........(155.0)..........Gorham to Stratton (9.85 days)
E14: 13.7 days...... (168.8)..........Stratton to Katahdin (13.6 days)
A16: Sample Mail label | E16: TABLE 2 -- Miles Per Day and Miles Per Hiking Day
A18: David P. Smith | E18: MPD ~~~~~~~ MPHD ~~~~~~ SECTION
A19: 2857 Godfrey Road | E19: 9.4 miles..........(10.1 miles).........Springer to Georgia Border (75.6 miles)
A20: Glen Rock, PA 17327 | E20: 11.2 miles........(12.0 miles).........Georgia Border to Fontana (87.5 miles)
E21: 12.2 miles........(14.0 miles).........Fontana to Damascus (297.1 miles)
E22: 13.4 miles........(15.9 miles).........Damascus to Waynesboro (388.6 miles)
E23: 14.4 miles........(16.8 miles).........Waynesboro to Harpers Ferry (161.1 miles)
E24: 13.9 miles........(16.8 miles).........Harpers Ferry to DWG (270.3 miles)
E25: 13.9 miles........(16.1 miles).........DWG to Kent (172.4 miles)
E26: 14.0 miles........(15.5 miles).........Kent to Glencliff (323.8 miles)
B27: David P. Smith | E27: 10.5 miles........(11.4 miles).........Glencliff to Gorham (100.6 miles)
B28: c/o General Delivery | E28: 11.1 miles........(12.5 miles).........Gorham to Stratton (110.1 miles)
B29: 2078 STATE HIGHWAY 60 | E29: 13.6 miles........(14.7 miles).........Stratton to Katahdin (187.9 miles)
B30: SUCHES, GA 30572-9998 | E30: 12.9 miles........(14.7 miles).........The entire AT (2175.0 miles)
A36: Please hold for Appalachian Trail Hiker
A38: Approximate Pick-Up Date: ____________________

Sheet PriceCalc
A2: Mail drops
A3: Re-supply
A4: hostels
A5: hotels
A6: eat out
A7: In town
A9: * Check Whiteblaze.net for details on PO's, hostels, shelters and other info.
